Workbook

Sheet DISTANCE
A1: Vehicle(s) RTO | B1: Start Time | C1: End Time | D1: Active Hours | E1: Total Distance (KM) | F1: Average Speed (KM/h)
A2: RJ14GL1238 | B2: 0.31666667 | C2: 0.65902778 | D2: 0.34174769 | E2: 134.59 | F2: 16.41
A3: RJ14GL6303 | B3: 0.31458333 | C3: 0.65763889 | D3: 0.34295139 | E3: 124.09 | F3: 15.08
A4: RJ41GA7237 | B4: 0.063888889 | C4: 0.65625 | D4: 0.59222222 | E4: 115.35 | F4: 8.12
A5: RJ14GF6617 | B5: 0.31944444 | C5: 0.65486111 | D5: 0.33540509 | E5: 114.34 | F5: 14.2
A6: RJ14GL6309 | B6: 0.32291667 | C6: 0.65763889 | D6: 0.33423611 | E6: 113.18 | F6: 14.11
A7: RJ14GU1705 | B7: 0.35416667 | C7: 0.63958333 | D7: 0.28553241 | E7: 110.88 | F7: 16.18
A8: RJ14GN4335 | B8: 0.31805556 | C8: 0.66111111 | D8: 0.34297454 | E8: 109.43 | F8: 13.29
A9: RJ14GL6300 | B9: 0.28958333 | C9: 0.63888889 | D9: 0.34915509 | E9: 108.5 | F9: 12.95
A10: RJ14GL6304 | B10: 0.32013889 | C10: 0.63958333 | D10: 0.3199537 | E10: 105.24 | F10: 13.71
A11: RJ14GL6308 | B11: 0.29236111 | C11: 0.65069444 | D11: 0.35844907 | E11: 101.05 | F11: 11.75
A12: RJ14GU1726 | B12: 0.35972222 | C12: 0.6625 | D12: 0.30318287 | E12: 98.24 | F12: 13.5
A13: RJ14GL6317 | B13: 0.31041667 | C13: 0.65694444 | D13: 0.34663194 | E13: 95 | F13: 11.42
... A572: RJ47GA6531 | B572: 0.22916667 | C572: 0.22916667 | D572: 0 | E572: 0 | F572: 0

Sheet COV
A1: MORNING_SVC09122 | B1: SVC09122 | C1: 89
A2: MORNING_RJ14GN8107 | B2: RJ14GN8107 | C2: 88
A3: MORNING_RJ47GA7193 | B3: RJ47GA7193 | C3: 93
A4: MORNING_RJ47GA7274 | B4: RJ47GA7274 | C4: 88
A5: MORNING_RJ47GA7282 | B5: RJ47GA7282 | C5: 87
A6: SWEEPING_4783SW | B6: RJ14GT8196SW | C6: 100
A7: MORNING_RJ14GN8108 | B7: RJ14GN8108 | C7: 82
A8: SWEEPING_RJ14GQ5287SW | B8: RJ14GQ5287SW | C8: 0
A9: MORNING_RJ14GT8112 | B9: RJ14GT8112 | C9: 91
A10: W39_SVD11055SW | B10: RJ14GT7546SW | C10: 100
A11: SWEEPING_RJ14GN5212SW | B11: RJ14GN5212SW | C11: 50
A12: MORNING_RJ14GN7682 | B12: RJ14GN7682 | C12: 89
... A437: MORNING_RJ14GN7670 | B437: RJ14GN7670 | C437: 100

Sheet ANZ
C1: ADARSH NAGAR ZONE
C2: AMRUT ENTERPRISES D2D HOPPERS
C3: =TODAY() -> 46178
C4: SR NO. | D4: Ward | E4: VEHICLE REG. NO. | F4: COVERED % | G4: Total Distance (KM) | H4: Average Speed (KM/h) | I4: REMARKS
A5: MORNING_RJ47GA7242 | C5: 1 | D5: Ward 76 - Ward - 76 | E5: =VLOOKUP(A5,COV!$1:$1048576,2,0) -> RJ47GA7242 | F5: =VLOOKUP(A5,COV!$1:$1048576,3,0) -> 89 | G5: =VLOOKUP(E5,DISTANCE!$1:$1048576,5,0) -> 14.65 | H5: =VLOOKUP(E5,DISTANCE!$1:$1048576,6,0) -> 4.34 | I5: =IF(F5<70,"DRIVER FAULT","")
A6: MORNING_RJ47GA7293 | C6: 2 | D6: Ward 76 - Ward - 76 | E6: =VLOOKUP(A6,COV!$1:$1048576,2,0) -> RJ47GA7293 | F6: =VLOOKUP(A6,COV!$1:$1048576,3,0) -> 81 | G6: =VLOOKUP(E6,DISTANCE!$1:$1048576,5,0) -> 18.75 | H6: =VLOOKUP(E6,DISTANCE!$1:$1048576,6,0) -> 5.42 | I6: =IF(F6<70,"DRIVER FAULT","")
A7: MORNING_RJ47GA7227 | C7: 3 | D7: Ward 76 - Ward - 76 | E7: =VLOOKUP(A7,COV!$1:$1048576,2,0) -> RJ47GA7227 | F7: =VLOOKUP(A7,COV!$1:$1048576,3,0) -> 81 | G7: =VLOOKUP(E7,DISTANCE!$1:$1048576,5,0) -> 21.08 | H7: =VLOOKUP(E7,DISTANCE!$1:$1048576,6,0) -> 3.18 | I7: =IF(F7<70,"DRIVER FAULT","")
A8: MORNING_RJ47GA7188 | C8: 4 | D8: Ward 77 - Ward - 77 | E8: =VLOOKUP(A8,COV!$1:$1048576,2,0) -> RJ47GA7188 | F8: =VLOOKUP(A8,COV!$1:$1048576,3,0) -> 83 | G8: =VLOOKUP(E8,DISTANCE!$1:$1048576,5,0) -> 19.87 | H8: =VLOOKUP(E8,DISTANCE!$1:$1048576,6,0) -> 1.26 | I8: =IF(F8<70,"DRIVER FAULT","")
A9: MORNING_RJ47GA7177 | C9: 5 | D9: Ward 77 - Ward - 77 | E9: =VLOOKUP(A9,COV!$1:$1048576,2,0) -> RJ47GA7177 | F9: =VLOOKUP(A9,COV!$1:$1048576,3,0) -> 90 | G9: =VLOOKUP(E9,DISTANCE!$1:$1048576,5,0) -> 46.87 | H9: =VLOOKUP(E9,DISTANCE!$1:$1048576,6,0) -> 3.78 | I9: =IF(F9<70,"DRIVER FAULT","")
A10: MORNING_RJ47GA7236 | C10: 6 | D10: Ward 78 - Ward - 78 | E10: =VLOOKUP(A10,COV!$1:$1048576,2,0) -> RJ47GA7236 | F10: =VLOOKUP(A10,COV!$1:$1048576,3,0) -> 74 | G10: =VLOOKUP(E10,DISTANCE!$1:$1048576,5,0) -> 18.12 | H10: =VLOOKUP(E10,DISTANCE!$1:$1048576,6,0) -> 2.23 | I10: =IF(F10<70,"DRIVER FAULT","")
A11: MORNING_RJ47GA7170 | C11: 7 | D11: Ward 78 - Ward - 78 | E11: =VLOOKUP(A11,COV!$1:$1048576,2,0) -> RJ47GA7170 | F11: =VLOOKUP(A11,COV!$1:$1048576,3,0) -> 100 | G11: =VLOOKUP(E11,DISTANCE!$1:$1048576,5,0) -> 22.33 | H11: =VLOOKUP(E11,DISTANCE!$1:$1048576,6,0) -> 1.42 | I11: =IF(F11<70,"DRIVER FAULT","")
A12: MORNING_RJ47GA7198 | C12: 8 | D12: Ward 78 - Ward - 78 | E12: =VLOOKUP(A12,COV!$1:$1048576,2,0) -> RJ47GA7198 | F12: =VLOOKUP(A12,COV!$1:$1048576,3,0) -> 81 | G12: =VLOOKUP(E12,DISTANCE!$1:$1048576,5,0) -> 25.78 | H12: =VLOOKUP(E12,DISTANCE!$1:$1048576,6,0) -> 6.75 | I12: =IF(F12<70,"DRIVER FAULT","")
A13: MORNING_RJ47GA7279 | C13: 9 | D13: Ward 79 - Ward - 79 | E13: =VLOOKUP(A13,COV!$1:$1048576,2,0) -> RJ47GA7279 | F13: =VLOOKUP(A13,COV!$1:$1048576,3,0) -> 94 | G13: =VLOOKUP(E13,DISTANCE!$1:$1048576,5,0) -> 36.9 | H13: =VLOOKUP(E13,DISTANCE!$1:$1048576,6,0) -> 5.16 | I13: =IF(F13<70,"DRIVER FAULT","")
A14: MORNING_RJ47GA7200 | C14: 10 | D14: Ward 79 - Ward - 79 | E14: =VLOOKUP(A14,COV!$1:$1048576,2,0) -> RJ47GA7200 | F14: =VLOOKUP(A14,COV!$1:$1048576,3,0) -> 94 | G14: =VLOOKUP(E14,DISTANCE!$1:$1048576,5,0) -> 32.65 | H14: =VLOOKUP(E14,DISTANCE!$1:$1048576,6,0) -> 3.76 | I14: =IF(F14<70,"DRIVER FAULT","")
A15: MORNING_RJ47GA7335 | C15: 11 | D15: Ward 80 - Ward - 80 | E15: =VLOOKUP(A15,COV!$1:$1048576,2,0) -> RJ47GA7335 | F15: =VLOOKUP(A15,COV!$1:$1048576,3,0) -> 100 | G15: =VLOOKUP(E15,DISTANCE!$1:$1048576,5,0) -> 23.87 | H15: =VLOOKUP(E15,DISTANCE!$1:$1048576,6,0) -> 3.63 | I15: =IF(F15<70,"DRIVER FAULT","")
A16: MORNING_RJ47GA7289 | C16: 12 | D16: Ward 80 - Ward - 80 | E16: =VLOOKUP(A16,COV!$1:$1048576,2,0) -> RJ47GA7289 | F16: GPS TAMPERED
A17: MORNING_RJ47GA7191 | C17: 13 | D17: Ward 81 - Ward - 81 | E17: =VLOOKUP(A17,COV!$1:$1048576,2,0) -> RJ47GA7191 | F17: =VLOOKUP(A17,COV!$1:$1048576,3,0) -> 90 | G17: =VLOOKUP(E17,DISTANCE!$1:$1048576,5,0) -> 15.18 | H17: =VLOOKUP(E17,DISTANCE!$1:$1048576,6,0) -> 6.08 | I17: =IF(F17<70,"DRIVER FAULT","")
A18: MORNING_RJ47GA7282 | C18: 14 | D18: Ward 81 - Ward - 81 | E18: =VLOOKUP(A18,COV!$1:$1048576,2,0) -> RJ47GA7282 | F18: =VLOOKUP(A18,COV!$1:$1048576,3,0) -> 87 | G18: =VLOOKUP(E18,DISTANCE!$1:$1048576,5,0) -> 26.09 | H18: =VLOOKUP(E18,DISTANCE!$1:$1048576,6,0) -> 4.5 | I18: =IF(F18<70,"DRIVER FAULT","")
A19: MORNING_RJ47GA7243 | C19: 15 | D19: Ward 82 - Ward - 82 | E19: =VLOOKUP(A19,COV!$1:$1048576,2,0) -> RJ47GA7243 | F19: =VLOOKUP(A19,COV!$1:$1048576,3,0) -> 96 | G19: =VLOOKUP(E19,DISTANCE!$1:$1048576,5,0) -> 17.48 | H19: =VLOOKUP(E19,DISTANCE!$1:$1048576,6,0) -> 4.58 | I19: =IF(F19<70,"DRIVER FAULT","")
A20: MORNING_RJ47GA7274 | C20: 16 | D20: Ward 82 - Ward - 82 | E20: =VLOOKUP(A20,COV!$1:$1048576,2,0) -> RJ47GA7274 | F20: =VLOOKUP(A20,COV!$1:$1048576,3,0) -> 88 | G20: =VLOOKUP(E20,DISTANCE!$1:$1048576,5,0) -> 13.62 | H20: =VLOOKUP(E20,DISTANCE!$1:$1048576,6,0) -> 1.81 | I20: =IF(F20<70,"DRIVER FAULT","")
A21: MORNING_RJ47GA7181 | C21: 17 | D21: Ward 83 - Ward - 83 | E21: =VLOOKUP(A21,COV!$1:$1048576,2,0) -> RJ47GA7288SW | F21: =VLOOKUP(A21,COV!$1:$1048576,3,0) -> 92 | G21: =VLOOKUP(E21,DISTANCE!$1:$1048576,5,0) -> 26.77 | H21: =VLOOKUP(E21,DISTANCE!$1:$1048576,6,0) -> 3.94 | I21: =IF(F21<70,"DRIVER FAULT","")
A22: MORNING_RJ47GA7178 | C22: 18 | D22: Ward 83 - Ward - 83 | E22: =VLOOKUP(A22,COV!$1:$1048576,2,0) -> RJ47GA7178 | F22: =VLOOKUP(A22,COV!$1:$1048576,3,0) -> 95 | G22: =VLOOKUP(E22,DISTANCE!$1:$1048576,5,0) -> 23.1 | H22: =VLOOKUP(E22,DISTANCE!$1:$1048576,6,0) -> 3.69 | I22: =IF(F22<70,"DRIVER FAULT","")
A23: MORNING_RJ47GA7180 | C23: 19 | D23: Ward 83 - Ward - 83 | E23: =VLOOKUP(A23,COV!$1:$1048576,2,0) -> RJ47GA7180 | F23: =VLOOKUP(A23,COV!$1:$1048576,3,0) -> 97 | G23: =VLOOKUP(E23,DISTANCE!$1:$1048576,5,0) -> 30.3 | H23: =VLOOKUP(E23,DISTANCE!$1:$1048576,6,0) -> 3.39 | I23: =IF(F23<70,"DRIVER FAULT","")
A24: MORNING_RJ47GA7331 | C24: 20 | D24: Ward 84 - Ward - 84 | E24: =VLOOKUP(A24,COV!$1:$1048576,2,0) -> RJ47GA7331 | F24: =VLOOKUP(A24,COV!$1:$1048576,3,0) -> 94 | G24: =VLOOKUP(E24,DISTANCE!$1:$1048576,5,0) -> 25.12 | H24: =VLOOKUP(E24,DISTANCE!$1:$1048576,6,0) -> 5.5 | I24: =IF(F24<70,"DRIVER FAULT","")
A25: MORNING_RJ47GA7342 | C25: 21 | D25: Ward 84 - Ward - 84 | E25: =VLOOKUP(A25,COV!$1:$1048576,2,0) -> RJ47GA7342 | F25: =VLOOKUP(A25,COV!$1:$1048576,3,0) -> 83 | G25: =VLOOKUP(E25,DISTANCE!$1:$1048576,5,0) -> 29.66 | H25: =VLOOKUP(E25,DISTANCE!$1:$1048576,6,0) -> 4.24 | I25: =IF(F25<70,"DRIVER FAULT","")
A26: MORNING_RJ47GA7192 | C26: 22 | D26: Ward 85 - Ward - 85 | E26: =VLOOKUP(A26,COV!$1:$1048576,2,0) -> RJ47GA7192 | F26: =VLOOKUP(A26,COV!$1:$1048576,3,0) -> 96 | G26: =VLOOKUP(E26,DISTANCE!$1:$1048576,5,0) -> 18.86 | H26: =VLOOKUP(E26,DISTANCE!$1:$1048576,6,0) -> 3.77 | I26: =IF(F26<70,"DRIVER FAULT","")
A27: MORNING_RJ47GA7270 | C27: 23 | D27: Ward 85 - Ward - 85 | E27: =VLOOKUP(A27,COV!$1:$1048576,2,0) -> RJ47GA7270 | F27: =VLOOKUP(A27,COV!$1:$1048576,3,0) -> 89 | G27: =VLOOKUP(E27,DISTANCE!$1:$1048576,5,0) -> 12.48 | H27: =VLOOKUP(E27,DISTANCE!$1:$1048576,6,0) -> 2.61 | I27: =IF(F27<70,"DRIVER FAULT","")
A28: MORNING_RJ47GA7176 | C28: 24 | D28: Ward 86 - Ward - 86 | E28: =VLOOKUP(A28,COV!$1:$1048576,2,0) -> RJ47GA7176 | F28: =VLOOKUP(A28,COV!$1:$1048576,3,0) -> 100 | G28: =VLOOKUP(E28,DISTANCE!$1:$1048576,5,0) -> 13.78 | H28: =VLOOKUP(E28,DISTANCE!$1:$1048576,6,0) -> 3.39 | I28: =IF(F28<70,"DRIVER FAULT","")
... A54: MORNING_RJ47GA7275 | C54: 50 | D54: Ward 98 - Ward - 98 | E54: =VLOOKUP(A54,COV!$1:$1048576,2,0) -> RJ47GA7275 | F54: =VLOOKUP(A54,COV!$1:$1048576,3,0) -> 100 | G54: =VLOOKUP(E54,DISTANCE!$1:$1048576,5,0) -> 64.25 | H54: =VLOOKUP(E54,DISTANCE!$1:$1048576,6,0) -> 10.16 | I54: =IF(F54<70,"DRIVER FAULT","")
A55: MORNING_RJ47GA7218 | C55: 51 | D55: Ward 99 - Ward - 99 | E55: =VLOOKUP(A55,COV!$1:$1048576,2,0) -> RJ47GA7175 | F55: GPS TAMPERED
A56: MORNING_RJ47GA7339 | C56: 52 | D56: Ward 99 - Ward - 99 | E56: =VLOOKUP(A56,COV!$1:$1048576,2,0) -> RJ47GA7339 | F56: =VLOOKUP(A56,COV!$1:$1048576,3,0) -> 93 | G56: =VLOOKUP(E56,DISTANCE!$1:$1048576,5,0) -> 49.39 | H56: =VLOOKUP(E56,DISTANCE!$1:$1048576,6,0) -> 5.78 | I56: =IF(F56<70,"DRIVER FAULT","")
A57: MORNING_RJ47GA7238 | C57: 53 | D57: Ward 99 - Ward - 99 | E57: =VLOOKUP(A57,COV!$1:$1048576,2,0) -> RJ47GA7238 | F57: =VLOOKUP(A57,COV!$1:$1048576,3,0) -> 97 | G57: =VLOOKUP(E57,DISTANCE!$1:$1048576,5,0) -> 36.31 | H57: =VLOOKUP(E57,DISTANCE!$1:$1048576,6,0) -> 4.24 | I57: =IF(F57<70,"DRIVER FAULT","")
A58: MORNING_RJ47GA7190 | C58: 54 | D58: Ward 100 - Ward - 100 | E58: =VLOOKUP(A58,COV!$1:$1048576,2,0) -> RJ47GA7190 | F58: =VLOOKUP(A58,COV!$1:$1048576,3,0) -> 69 | G58: =VLOOKUP(E58,DISTANCE!$1:$1048576,5,0) -> 47.69 | H58: =VLOOKUP(E58,DISTANCE!$1:$1048576,6,0) -> 6.08 | I58: =IF(F58<70,"DRIVER FAULT","") -> DRIVER FAULT
A59: MORNING_RJ47GA7341 | C59: 55 | D59: Ward 100 - Ward - 100 | E59: =VLOOKUP(A59,COV!$1:$1048576,2,0) -> RJ47GA7341 | F59: NOT WORKED
A60: MORNING_RJ47GA7237 | C60: 56 | D60: Ward 100 - Ward - 100 | E60: =VLOOKUP(A60,COV!$1:$1048576,2,0) -> RJ47GA7237 | F60: =VLOOKUP(A60,COV!$1:$1048576,3,0) -> 70 | G60: =VLOOKUP(E60,DISTANCE!$1:$1048576,5,0) -> 48.41 | H60: =VLOOKUP(E60,DISTANCE!$1:$1048576,6,0) -> 6.05 | I60: =IF(F60<70,"DRIVER FAULT","")
A61: MORNING_RJ47GA7183 | C61: 57 | D61: Ward 100 - Ward - 100 | E61: =VLOOKUP(A61,COV!$1:$1048576,2,0) -> RJ47GA7183 | F61: =VLOOKUP(A61,COV!$1:$1048576,3,0) -> 56 | G61: =VLOOKUP(E61,DISTANCE!$1:$1048576,5,0) -> 50.22 | H61: =VLOOKUP(E61,DISTANCE!$1:$1048576,6,0) -> 5.85 | I61: =IF(F61<70,"DRIVER FAULT","") -> DRIVER FAULT
A62: MORNING_RJ47GA7184 | C62: 58 | D62: Ward 100 - Ward - 100 | E62: =VLOOKUP(A62,COV!$1:$1048576,2,0) -> RJ47GA7184 | F62: =VLOOKUP(A62,COV!$1:$1048576,3,0) -> 72 | G62: =VLOOKUP(E62,DISTANCE!$1:$1048576,5,0) -> 80.78 | H62: =VLOOKUP(E62,DISTANCE!$1:$1048576,6,0) -> 9.82 | I62: =IF(F62<70,"DRIVER FAULT","")
A63: MORNING_RJ47GA7278 | C63: 59 | D63: Ward 132 - Ward - 132 | E63: =VLOOKUP(A63,COV!$1:$1048576,2,0) -> RJ47GA7278 | F63: =VLOOKUP(A63,COV!$1:$1048576,3,0) -> 50 | G63: =VLOOKUP(E63,DISTANCE!$1:$1048576,5,0) -> 76.95 | H63: =VLOOKUP(E63,DISTANCE!$1:$1048576,6,0) -> 9.13 | I63: =IF(F63<70,"DRIVER FAULT","") -> DRIVER FAULT
A64: MORNING_RJ47GA7240 | C64: 60 | D64: Ward 132 - Ward - 132 | E64: =VLOOKUP(A64,COV!$1:$1048576,2,0) -> RJ47GA7240 | F64: =VLOOKUP(A64,COV!$1:$1048576,3,0) -> 91 | G64: =VLOOKUP(E64,DISTANCE!$1:$1048576,5,0) -> 54.38 | H64: =VLOOKUP(E64,DISTANCE!$1:$1048576,6,0) -> 3.5 | I64: =IF(F64<70,"DRIVER FAULT","")
A65: MORNING_RJ47GA7246 | C65: 61 | D65: Ward 132 - Ward - 132 | E65: =VLOOKUP(A65,COV!$1:$1048576,2,0) -> RJ47GA7246 | F65: =VLOOKUP(A65,COV!$1:$1048576,3,0) -> 86 | G65: =VLOOKUP(E65,DISTANCE!$1:$1048576,5,0) -> 57 | H65: =VLOOKUP(E65,DISTANCE!$1:$1048576,6,0) -> 9.1 | I65: =IF(F65<70,"DRIVER FAULT","")
...

Sheet KPZ
C1: KISHANPOLE ZONE
C2: WeVOIS LABS PVT LTD. D2D HOPPERS
C3: =TODAY() -> 46178
C4: SR NO. | D4: Ward | E4: VEHICLE REG. NO. | F4: COVERED % | G4: TOTAL DISTANCE | H4: Average Speed (KM/h) | I4: REMARKS
A5: MORNING_RJ14GT9472 | C5: 1 | D5: WARD 55 - WARD - 55 | E5: =VLOOKUP(A5,COV!$1:$1048576,2,0) -> RJ14GT9472 | F5: =VLOOKUP(A5,COV!$1:$1048576,3,0) -> 91 | G5: =VLOOKUP(E5,DISTANCE!$1:$1048576,5,0) -> 16.32 | H5: =VLOOKUP(E5,DISTANCE!$1:$1048576,6,0) -> 3.18 | I5: =IF(F5<70,"DRIVER FAULT","")
A6: MORNING_RJ14GT8921 | C6: 2 | D6: WARD 55 - WARD - 55 | E6: =VLOOKUP(A6,COV!$1:$1048576,2,0) -> RJ14GT8921 | F6: =VLOOKUP(A6,COV!$1:$1048576,3,0) -> 93 | G6: =VLOOKUP(E6,DISTANCE!$1:$1048576,5,0) -> 28.48 | H6: =VLOOKUP(E6,DISTANCE!$1:$1048576,6,0) -> 7.29 | I6: =IF(F6<70,"DRIVER FAULT","")
A7: MORNING_RJ14GT9483 | C7: 3 | D7: WARD 56 - WARD - 56 | E7: =VLOOKUP(A7,COV!$1:$1048576,2,0) -> RJ14GT9483 | F7: =VLOOKUP(A7,COV!$1:$1048576,3,0) -> 86 | G7: =VLOOKUP(E7,DISTANCE!$1:$1048576,5,0) -> 16.51 | H7: =VLOOKUP(E7,DISTANCE!$1:$1048576,6,0) -> 3.87 | I7: =IF(F7<70,"DRIVER FAULT","")
A8: MORNING_RJ14GT9461 | C8: 4 | D8: WARD 56 - WARD - 56 | E8: =VLOOKUP(A8,COV!$1:$1048576,2,0) -> RJ14GT9461 | F8: =VLOOKUP(A8,COV!$1:$1048576,3,0) -> 92 | G8: =VLOOKUP(E8,DISTANCE!$1:$1048576,5,0) -> 20.45 | H8: =VLOOKUP(E8,DISTANCE!$1:$1048576,6,0) -> 4.09 | I8: =IF(F8<70,"DRIVER FAULT","")
A9: MORNING_ RJ14GT8849 | C9: 5 | D9: WARD 57 - WARD - 57 | E9: =VLOOKUP(A9,COV!$1:$1048576,2,0) -> RJ14GT8849 | F9: =VLOOKUP(A9,COV!$1:$1048576,3,0) -> 97 | G9: =VLOOKUP(E9,DISTANCE!$1:$1048576,5,0) -> 27.27 | H9: =VLOOKUP(E9,DISTANCE!$1:$1048576,6,0) -> 4.15 | I9: =IF(F9<70,"DRIVER FAULT","")
A10: MORNING_RJ14GT9038 | C10: 6 | D10: WARD 57 - WARD - 57 | E10: =VLOOKUP(A10,COV!$1:$1048576,2,0) -> RJ14GT9038 | F10: =VLOOKUP(A10,COV!$1:$1048576,3,0) -> 90 | G10: =VLOOKUP(E10,DISTANCE!$1:$1048576,5,0) -> 14.47 | H10: =VLOOKUP(E10,DISTANCE!$1:$1048576,6,0) -> 2.14 | I10: =IF(F10<70,"DRIVER FAULT","")
A11: MORNING_ RJ14GT9480 | C11: 7 | D11: WARD 58 - WARD - 58 | E11: =VLOOKUP(A11,COV!$1:$1048576,2,0) -> RJ14GT9480 | F11: =VLOOKUP(A11,COV!$1:$1048576,3,0) -> 86 | G11: =VLOOKUP(E11,DISTANCE!$1:$1048576,5,0) -> 21.75 | H11: =VLOOKUP(E11,DISTANCE!$1:$1048576,6,0) -> 2.42 | I11: =IF(F11<70,"DRIVER FAULT","")
A12: MORNING_RJ14GT9475 | C12: 8 | D12: WARD 58 - WARD - 58 | E12: =VLOOKUP(A12,COV!$1:$1048576,2,0) -> RJ14GT9475 | F12: =VLOOKUP(A12,COV!$1:$1048576,3,0) -> 100 | G12: =VLOOKUP(E12,DISTANCE!$1:$1048576,5,0) -> 41.28 | H12: =VLOOKUP(E12,DISTANCE!$1:$1048576,6,0) -> 7.71 | I12: =IF(F12<70,"DRIVER FAULT","")
A13: MORNING_ RJ14GT9042 | C13: 9 | D13: WARD 59 - WARD - 59 | E13: =VLOOKUP(A13,COV!$1:$1048576,2,0) -> RJ14GT9042 | F13: =VLOOKUP(A13,COV!$1:$1048576,3,0) -> 97 | G13: =VLOOKUP(E13,DISTANCE!$1:$1048576,5,0) -> 15.75 | H13: =VLOOKUP(E13,DISTANCE!$1:$1048576,6,0) -> 3.18 | I13: =IF(F13<70,"DRIVER FAULT","")
A14: MORNING_ RJ14GT8165 | C14: 10 | D14: WARD 59 - WARD - 59 | E14: =VLOOKUP(A14,COV!$1:$1048576,2,0) -> RJ14GT8165 | F14: =VLOOKUP(A14,COV!$1:$1048576,3,0) -> 98 | G14: =VLOOKUP(E14,DISTANCE!$1:$1048576,5,0) -> 16.01 | H14: =VLOOKUP(E14,DISTANCE!$1:$1048576,6,0) -> 1.98 | I14: =IF(F14<70,"DRIVER FAULT","")
A15: MORNING_RJ14GT8920 | C15: 11 | D15: WARD 60 - WARD - 60 | E15: =VLOOKUP(A15,COV!$1:$1048576,2,0) -> RJ14GT8920 | F15: =VLOOKUP(A15,COV!$1:$1048576,3,0) -> 96 | G15: =VLOOKUP(E15,DISTANCE!$1:$1048576,5,0) -> 19.75 | H15: =VLOOKUP(E15,DISTANCE!$1:$1048576,6,0) -> 4.13 | I15: =IF(F15<70,"DRIVER FAULT","")
A16: MORNING_ RJ14GT9048 | C16: 12 | D16: WARD 60 - WARD - 60 | E16: =VLOOKUP(A16,COV!$1:$1048576,2,0) -> RJ14GT9048 | F16: =VLOOKUP(A16,COV!$1:$1048576,3,0) -> 86 | G16: =VLOOKUP(E16,DISTANCE!$1:$1048576,5,0) -> 23.66 | H16: =VLOOKUP(E16,DISTANCE!$1:$1048576,6,0) -> 3.96 | I16: =IF(F16<70,"DRIVER FAULT","")
A17: MORNING_ RJ14GT8099 | C17: 13 | D17: WARD 61 - WARD - 61 | E17: =VLOOKUP(A17,COV!$1:$1048576,2,0) -> RJ14GT8099 | F17: =VLOOKUP(A17,COV!$1:$1048576,3,0) -> 85 | G17: =VLOOKUP(E17,DISTANCE!$1:$1048576,5,0) -> 21.22 | H17: =VLOOKUP(E17,DISTANCE!$1:$1048576,6,0) -> 4.53 | I17: =IF(F17<70,"DRIVER FAULT","")
A18: MORNING_ RJ14GT8976 | C18: 14 | D18: WARD 61 - WARD - 61 | E18: =VLOOKUP(A18,COV!$1:$1048576,2,0) -> RJ14GT8976 | F18: REPLACED BY 8844 (GPS TAMPERED)
A19: MORNING_RJ14GT8840 | C19: 15 | D19: WARD 62 - WARD - 62 | E19: =VLOOKUP(A19,COV!$1:$1048576,2,0) -> RJ14GT8840 | F19: =VLOOKUP(A19,COV!$1:$1048576,3,0) -> 78 | G19: =VLOOKUP(E19,DISTANCE!$1:$1048576,5,0) -> 28.24 | H19: =VLOOKUP(E19,DISTANCE!$1:$1048576,6,0) -> 4.43 | I19: =IF(F19<70,"DRIVER FAULT","")
A20: MORNING_ RJ14GT9465 | C20: 16 | D20: WARD 62 - WARD - 62 | E20: =VLOOKUP(A20,COV!$1:$1048576,2,0) -> RJ14GT9465 | F20: =VLOOKUP(A20,COV!$1:$1048576,3,0) -> 83 | G20: =VLOOKUP(E20,DISTANCE!$1:$1048576,5,0) -> 21.24 | H20: =VLOOKUP(E20,DISTANCE!$1:$1048576,6,0) -> 3.62 | I20: =IF(F20<70,"DRIVER FAULT","")
A21: MORNING_ RJ14GT8923 | C21: 17 | D21: WARD 63 - WARD - 63 | E21: =VLOOKUP(A21,COV!$1:$1048576,2,0) -> RJ14GT8923 | F21: =VLOOKUP(A21,COV!$1:$1048576,3,0) -> 98 | G21: =VLOOKUP(E21,DISTANCE!$1:$1048576,5,0) -> 14.73 | H21: =VLOOKUP(E21,DISTANCE!$1:$1048576,6,0) -> 1.99 | I21: =IF(F21<70,"DRIVER FAULT","")
A22: MORNING_ RJ14GT8158 | C22: 18 | D22: WARD 63 - WARD - 63 | E22: =VLOOKUP(A22,COV!$1:$1048576,2,0) -> RJ14GT9975 | F22: =VLOOKUP(A22,COV!$1:$1048576,3,0) -> 96 | G22: =VLOOKUP(E22,DISTANCE!$1:$1048576,5,0) -> 14.62 | H22: =VLOOKUP(E22,DISTANCE!$1:$1048576,6,0) -> 2.79 | I22: =IF(F22<70,"DRIVER FAULT","")
A23: MORNING_ RJ14GT8966 | C23: 19 | D23: WARD 64 - WARD - 64 | E23: =VLOOKUP(A23,COV!$1:$1048576,2,0) -> RJ14GT8966 | F23: =VLOOKUP(A23,COV!$1:$1048576,3,0) -> 100 | G23: =VLOOKUP(E23,DISTANCE!$1:$1048576,5,0) -> 25.09 | H23: =VLOOKUP(E23,DISTANCE!$1:$1048576,6,0) -> 4.64 | I23: =IF(F23<70,"DRIVER FAULT","")
A24: MORNING_ RJ14GT9470 | C24: 20 | D24: WARD 64 - WARD - 64 | E24: =VLOOKUP(A24,COV!$1:$1048576,2,0) -> RJ14GU0636 | F24: =VLOOKUP(A24,COV!$1:$1048576,3,0) -> 100 | G24: =VLOOKUP(E24,DISTANCE!$1:$1048576,5,0) -> 14.64 | H24: =VLOOKUP(E24,DISTANCE!$1:$1048576,6,0) -> 2.78 | I24: =IF(F24<70,"DRIVER FAULT","")
A25: MORNING_ RJ14GT9462 | C25: 21 | D25: WARD 65 - WARD - 65 | E25: =VLOOKUP(A25,COV!$1:$1048576,2,0) -> RJ14GT9462 | F25: =VLOOKUP(A25,COV!$1:$1048576,3,0) -> 60 | G25: =VLOOKUP(E25,DISTANCE!$1:$1048576,5,0) -> 11.37 | H25: =VLOOKUP(E25,DISTANCE!$1:$1048576,6,0) -> 2.22 | I25: =IF(F25<70,"DRIVER FAULT","") -> DRIVER FAULT
A26: MORNING_ RJ14GT9033 | C26: 22 | D26: WARD 65 - WARD - 65 | E26: =VLOOKUP(A26,COV!$1:$1048576,2,0) -> RJ14GT9033 | F26: =VLOOKUP(A26,COV!$1:$1048576,3,0) -> 100 | G26: =VLOOKUP(E26,DISTANCE!$1:$1048576,5,0) -> 21.83 | H26: =VLOOKUP(E26,DISTANCE!$1:$1048576,6,0) -> 4.53 | I26: =IF(F26<70,"DRIVER FAULT","")
A27: MORNING_RJ14GT8853 | C27: 23 | D27: WARD 66 - WARD - 66 | E27: =VLOOKUP(A27,COV!$1:$1048576,2,0) -> RJ14GT8853 | F27: =VLOOKUP(A27,COV!$1:$1048576,3,0) -> 82 | G27: =VLOOKUP(E27,DISTANCE!$1:$1048576,5,0) -> 21.43 | H27: =VLOOKUP(E27,DISTANCE!$1:$1048576,6,0) -> 4.92 | I27: =IF(F27<70,"DRIVER FAULT","")
A28: MORNING_ RJ14GT8161 | C28: 24 | D28: WARD 66 - WARD - 66 | E28: =VLOOKUP(A28,COV!$1:$1048576,2,0) -> RJ14GT8161 | F28: =VLOOKUP(A28,COV!$1:$1048576,3,0) -> 93 | G28: =VLOOKUP(E28,DISTANCE!$1:$1048576,5,0) -> 7.99 | H28: =VLOOKUP(E28,DISTANCE!$1:$1048576,6,0) -> 2.74 | I28: =IF(F28<70,"DRIVER FAULT","")
A29: MORNING_ RJ14GT8162 | C29: 25 | D29: WARD 67 - WARD - 67 | E29: =VLOOKUP(A29,COV!$1:$1048576,2,0) -> RJ14GT8162 | F29: =VLOOKUP(A29,COV!$1:$1048576,3,0) -> 93 | G29: =VLOOKUP(E29,DISTANCE!$1:$1048576,5,0) -> 26.74 | H29: =VLOOKUP(E29,DISTANCE!$1:$1048576,6,0) -> 4.28 | I29: =IF(F29<70,"DRIVER FAULT","")
A30: MORNING_ RJ14GT9479 | C30: 26 | D30: WARD 67 - WARD - 67 | E30: =VLOOKUP(A30,COV!$1:$1048576,2,0) -> RJ14GT9479 | F30: =VLOOKUP(A30,COV!$1:$1048576,3,0) -> 95 | G30: =VLOOKUP(E30,DISTANCE!$1:$1048576,5,0) -> 28.25 | H30: =VLOOKUP(E30,DISTANCE!$1:$1048576,6,0) -> 7.66 | I30: =IF(F30<70,"DRIVER FAULT","")
... A46: MORNING_RJ14GT8960 | C46: 42 | D46: WARD 75 - WARD - 75 | E46: =VLOOKUP(A46,COV!$1:$1048576,2,0) -> RJ14GT8960 | F46: =VLOOKUP(A46,COV!$1:$1048576,3,0) -> 100 | G46: =VLOOKUP(E46,DISTANCE!$1:$1048576,5,0) -> 43.14 | H46: =VLOOKUP(E46,DISTANCE!$1:$1048576,6,0) -> 4.03 | I46: =IF(F46<70,"DRIVER FAULT","")
C47: AVERAGE | F47: =AVERAGE(F5:F46) -> 91.219512 | G47: =AVERAGE(G5:G46) -> 23.302439 | H47: =AVERAGE(H5:H46) -> 4.4460976

Sheet CLZ
C1: CIVIL LINES ZONE
C2: WE VOIS LABS PVT LTD D2D HOPPER REPORT
C3: =TODAY() -> 46178
C4: SR NO. | D4: Ward | E4: VEHICLE REG. NO. | F4: COVERED % | G4: Total Distance (KM) | H4: Average Speed (KM/h) | I4: REMARK
A5: MORNING_RJ14GT8126 | C5: 1 | D5: WARD 31 - WARD - 31 | E5: =VLOOKUP(A5,COV!$1:$1048576,2,0) -> RJ14GT8126 | F5: =VLOOKUP(A5,COV!$1:$1048576,3,0) -> 94 | G5: =VLOOKUP(E5,DISTANCE!$1:$1048576,5,0) -> 28.09 | H5: =VLOOKUP(E5,DISTANCE!$1:$1048576,6,0) -> 5.36 | I5: =IF(F5<70,"DRIVER FAULT","")
A6: MORNING_RJ14GT8106 | C6: 2 | D6: WARD 31 - WARD - 31 | E6: =VLOOKUP(A6,COV!$1:$1048576,2,0) -> RJ14GT8106 | F6: =VLOOKUP(A6,COV!$1:$1048576,3,0) -> 91 | G6: =VLOOKUP(E6,DISTANCE!$1:$1048576,5,0) -> 22.17 | H6: =VLOOKUP(E6,DISTANCE!$1:$1048576,6,0) -> 2.9 | I6: =IF(F6<70,"DRIVER FAULT","")
A7: MORNING_RJ14GT8112 | C7: 3 | D7: WARD 31 - WARD - 31 | E7: =VLOOKUP(A7,COV!$1:$1048576,2,0) -> RJ14GT8112 | F7: =VLOOKUP(A7,COV!$1:$1048576,3,0) -> 91 | G7: =VLOOKUP(E7,DISTANCE!$1:$1048576,5,0) -> 40.59 | H7: =VLOOKUP(E7,DISTANCE!$1:$1048576,6,0) -> 9.05 | I7: =IF(F7<70,"DRIVER FAULT","")
A8: MORNING_RJ14GT8105 | C8: 4 | D8: WARD 32 - WARD - 32 | E8: =VLOOKUP(A8,COV!$1:$1048576,2,0) -> RJ14GT8105 | F8: =VLOOKUP(A8,COV!$1:$1048576,3,0) -> 90 | G8: =VLOOKUP(E8,DISTANCE!$1:$1048576,5,0) -> 26.11 | H8: =VLOOKUP(E8,DISTANCE!$1:$1048576,6,0) -> 3.34 | I8: =IF(F8<70,"DRIVER FAULT","")
A9: MORNING_SVC09122 | C9: 5 | D9: WARD 32 - WARD - 32 | E9: =VLOOKUP(A9,COV!$1:$1048576,2,0) -> SVC09122 | F9: =VLOOKUP(A9,COV!$1:$1048576,3,0) -> 89 | G9: =VLOOKUP(E9,DISTANCE!$1:$1048576,5,0) -> 39.94 | H9: =VLOOKUP(E9,DISTANCE!$1:$1048576,6,0) -> 4.29 | I9: =IF(F9<70,"DRIVER FAULT","")
A10: MORNING_RJ14GT9036 | C10: 6 | D10: WARD 33 - WARD - 33 | E10: =VLOOKUP(A10,COV!$1:$1048576,2,0) -> RJ14GT9036 | F10: =VLOOKUP(A10,COV!$1:$1048576,3,0) -> 100 | G10: =VLOOKUP(E10,DISTANCE!$1:$1048576,5,0) -> 13.11 | H10: =VLOOKUP(E10,DISTANCE!$1:$1048576,6,0) -> 1.52 | I10: =IF(F10<70,"DRIVER FAULT","")
A11: MORNING_RJ14GT8110 | C11: 7 | D11: WARD 33 - WARD - 33 | E11: =VLOOKUP(A11,COV!$1:$1048576,2,0) -> RJ14GT8110 | F11: =VLOOKUP(A11,COV!$1:$1048576,3,0) -> 93 | G11: =VLOOKUP(E11,DISTANCE!$1:$1048576,5,0) -> 13.08 | H11: =VLOOKUP(E11,DISTANCE!$1:$1048576,6,0) -> 2.45 | I11: =IF(F11<70,"DRIVER FAULT","")
A12: MORNING_RJ14GT7552 | C12: 8 | D12: WARD 33 - WARD - 33 | E12: =VLOOKUP(A12,COV!$1:$1048576,2,0) -> RJ14GT7552 | F12: =VLOOKUP(A12,COV!$1:$1048576,3,0) -> 100 | G12: =VLOOKUP(E12,DISTANCE!$1:$1048576,5,0) -> 15.88 | H12: =VLOOKUP(E12,DISTANCE!$1:$1048576,6,0) -> 3.03 | I12: =IF(F12<70,"DRIVER FAULT","")
A13: MORNING_RJ14GT8386 | C13: 9 | D13: WARD 34 - WARD - 34 | E13: =VLOOKUP(A13,COV!$1:$1048576,2,0) -> RJ14GT8386 | F13: =VLOOKUP(A13,COV!$1:$1048576,3,0) -> 96 | G13: =VLOOKUP(E13,DISTANCE!$1:$1048576,5,0) -> 21.2 | H13: =VLOOKUP(E13,DISTANCE!$1:$1048576,6,0) -> 2.89 | I13: =IF(F13<70,"DRIVER FAULT","")
A14: MORNING_RJ14GT7541 | C14: 10 | D14: WARD 34 - WARD - 34 | E14: =VLOOKUP(A14,COV!$1:$1048576,2,0) -> RJ14GT7541 | F14: =VLOOKUP(A14,COV!$1:$1048576,3,0) -> 92 | G14: =VLOOKUP(E14,DISTANCE!$1:$1048576,5,0) -> 24.81 | H14: =VLOOKUP(E14,DISTANCE!$1:$1048576,6,0) -> 3.58 | I14: =IF(F14<70,"DRIVER FAULT","")
A15: MORNING_RJ14GT8132 | C15: 11 | D15: WARD 34 - WARD - 34 | E15: =VLOOKUP(A15,COV!$1:$1048576,2,0) -> RJ14GT8132 | F15: =VLOOKUP(A15,COV!$1:$1048576,3,0) -> 93 | G15: =VLOOKUP(E15,DISTANCE!$1:$1048576,5,0) -> 46.25 | H15: =VLOOKUP(E15,DISTANCE!$1:$1048576,6,0) -> 4.14 | I15: =IF(F15<70,"DRIVER FAULT","")
A16: MORNING_RJ14GT8826 | C16: 12 | D16: WARD 35 - WARD - 35 | E16: =VLOOKUP(A16,COV!$1:$1048576,2,0) -> RJ14GT8826 | F16: =VLOOKUP(A16,COV!$1:$1048576,3,0) -> 91 | G16: =VLOOKUP(E16,DISTANCE!$1:$1048576,5,0) -> 11.64 | H16: =VLOOKUP(E16,DISTANCE!$1:$1048576,6,0) -> 2.32 | I16: =IF(F16<70,"DRIVER FAULT","")
... A47: MORNING_RJ14GT8116 | C47: 43 | D47: WARD 46 - WARD - 46 | E47: =VLOOKUP(A47,COV!$1:$1048576,2,0) -> RJ14GT8116 | F47: =VLOOKUP(A47,COV!$1:$1048576,3,0) -> 98 | G47: =VLOOKUP(E47,DISTANCE!$1:$1048576,5,0) -> 26 | H47: =VLOOKUP(E47,DISTANCE!$1:$1048576,6,0) -> 4.21 | I47: =IF(F47<70,"DRIVER FAULT","")
A48: MORNING_RJ14GT8855 | C48: 44 | D48: WARD 46 - WARD - 46 | E48: =VLOOKUP(A48,COV!$1:$1048576,2,0) -> RJ14GT8855 | F48: REPLACED BY 1031 (GPS TAMPERED)
A49: MORNING_RJ14GT8237 | C49: 45 | D49: WARD 46 - WARD - 46 | E49: =VLOOKUP(A49,COV!$1:$1048576,2,0) -> RJ14GT8237 | F49: =VLOOKUP(A49,COV!$1:$1048576,3,0) -> 92 | G49: =VLOOKUP(E49,DISTANCE!$1:$1048576,5,0) -> 57.42 | H49: =VLOOKUP(E49,DISTANCE!$1:$1048576,6,0) -> 5.64 | I49: =IF(F49<70,"DRIVER FAULT","")
A50: MORNING_RJ14GT7574 | C50: 46 | D50: WARD 47 - WARD - 47 | E50: =VLOOKUP(A50,COV!$1:$1048576,2,0) -> RJ14GT7574 | F50: =VLOOKUP(A50,COV!$1:$1048576,3,0) -> 45 | G50: =VLOOKUP(E50,DISTANCE!$1:$1048576,5,0) -> 32.29 | H50: =VLOOKUP(E50,DISTANCE!$1:$1048576,6,0) -> 4.71 | I50: =IF(F50<70,"DRIVER FAULT","") -> DRIVER FAULT
A51: MORNING_SVE15002 | C51: 47 | D51: WARD 47 - WARD - 47 | E51: =VLOOKUP(A51,COV!$1:$1048576,2,0) -> SVE15002 | F51: =VLOOKUP(A51,COV!$1:$1048576,3,0) -> 91 | G51: =VLOOKUP(E51,DISTANCE!$1:$1048576,5,0) -> 46.85 | H51: =VLOOKUP(E51,DISTANCE!$1:$1048576,6,0) -> 5.54 | I51: =IF(F51<70,"DRIVER FAULT","")
A52: MORNING_RJ14GT8303 | C52: 48 | D52: WARD 47 - WARD - 47 | E52: =VLOOKUP(A52,COV!$1:$1048576,2,0) -> RJ14GT8303 | F52: =VLOOKUP(A52,COV!$1:$1048576,3,0) -> 91 | G52: =VLOOKUP(E52,DISTANCE!$1:$1048576,5,0) -> 49.59 | H52: =VLOOKUP(E52,DISTANCE!$1:$1048576,6,0) -> 5.83 | I52: =IF(F52<70,"DRIVER FAULT","")
A53: MORNING_SVF17994 | C53: 49 | D53: WARD 47 - WARD - 47 | E53: =VLOOKUP(A53,COV!$1:$1048576,2,0) -> SVF18994 | F53: =VLOOKUP(A53,COV!$1:$1048576,3,0) -> 86 | G53: =VLOOKUP(E53,DISTANCE!$1:$1048576,5,0) -> 36.37 | H53: =VLOOKUP(E53,DISTANCE!$1:$1048576,6,0) -> 4.94 | I53: =IF(F53<70,"DRIVER FAULT","")
A54: MORNING_RJ14GT8845 | C54: 50 | D54: WARD 48 - WARD - 48 | E54: =VLOOKUP(A54,COV!$1:$1048576,2,0) -> RJ14GT8845 | F54: =VLOOKUP(A54,COV!$1:$1048576,3,0) -> 94 | G54: =VLOOKUP(E54,DISTANCE!$1:$1048576,5,0) -> 39.44 | H54: =VLOOKUP(E54,DISTANCE!$1:$1048576,6,0) -> 3.91 | I54: =IF(F54<70,"DRIVER FAULT","")
A55: MORNING_RJ14GT8822 | C55: 51 | D55: WARD 48 - WARD - 48 | E55: =VLOOKUP(A55,COV!$1:$1048576,2,0) -> RJ14GT8822 | F55: =VLOOKUP(A55,COV!$1:$1048576,3,0) -> 96 | G55: =VLOOKUP(E55,DISTANCE!$1:$1048576,5,0) -> 42.2 | H55: =VLOOKUP(E55,DISTANCE!$1:$1048576,6,0) -> 2.77 | I55: =IF(F55<70,"DRIVER FAULT","")
A56: MORNING_RJ14GT8824 | C56: 52 | D56: WARD 48 - WARD - 48 | E56: =VLOOKUP(A56,COV!$1:$1048576,2,0) -> RJ14GT8824 | F56: =VLOOKUP(A56,COV!$1:$1048576,3,0) -> 91 | G56: =VLOOKUP(E56,DISTANCE!$1:$1048576,5,0) -> 43.95 | H56: =VLOOKUP(E56,DISTANCE!$1:$1048576,6,0) -> 5.53 | I56: =IF(F56<70,"DRIVER FAULT","")
A57: MORNING_RJ14GT8825 | C57: 53 | D57: WARD 49 - WARD - 49 | E57: =VLOOKUP(A57,COV!$1:$1048576,2,0) -> RJ14GT8825 | F57: =VLOOKUP(A57,COV!$1:$1048576,3,0) -> 91 | G57: =VLOOKUP(E57,DISTANCE!$1:$1048576,5,0) -> 69.55 | H57: =VLOOKUP(E57,DISTANCE!$1:$1048576,6,0) -> 8.01 | I57: =IF(F57<70,"DRIVER FAULT","")
A58: MORNING_RJ14GT8169 | C58: 54 | D58: WARD 49 - WARD - 49 | E58: =VLOOKUP(A58,COV!$1:$1048576,2,0) -> RJ14GT8169 | F58: =VLOOKUP(A58,COV!$1:$1048576,3,0) -> 100 | G58: =VLOOKUP(E58,DISTANCE!$1:$1048576,5,0) -> 46.2 | H58: =VLOOKUP(E58,DISTANCE!$1:$1048576,6,0) -> 6.9 | I58: =IF(F58<70,"DRIVER FAULT","")
A59: MORNING_RJ14GT8815 | C59: 55 | D59: WARD 49 - WARD - 49 | E59: =VLOOKUP(A59,COV!$1:$1048576,2,0) -> RJ14GT8815 | F59: =VLOOKUP(A59,COV!$1:$1048576,3,0) -> 89 | G59: =VLOOKUP(E59,DISTANCE!$1:$1048576,5,0) -> 54.88 | H59: =VLOOKUP(E59,DISTANCE!$1:$1048576,6,0) -> 5.73 | I59: =IF(F59<70,"DRIVER FAULT","")
A60: MORNING_RJ14GT8823 | C60: 56 | D60: WARD 49 - WARD - 49 | E60: =VLOOKUP(A60,COV!$1:$1048576,2,0) -> RJ14GT8823 | F60: =VLOOKUP(A60,COV!$1:$1048576,3,0) -> 87 | G60: =VLOOKUP(E60,DISTANCE!$1:$1048576,5,0) -> 41.36 | H60: =VLOOKUP(E60,DISTANCE!$1:$1048576,6,0) -> 5.92 | I60: =IF(F60<70,"DRIVER FAULT","")
... A75: MORNING_RJ14GT8832 | C75: 71 | D75: WARD 54 - WARD - 54 | E75: =VLOOKUP(A75,COV!$1:$1048576,2,0) -> RJ14GT8832 | F75: =VLOOKUP(A75,COV!$1:$1048576,3,0) -> 91 | G75: =VLOOKUP(E75,DISTANCE!$1:$1048576,5,0) -> 43.08 | H75: =VLOOKUP(E75,DISTANCE!$1:$1048576,6,0) -> 4.33 | I75: =IF(F75<70,"DRIVER FAULT","")
C76: AVERAGE | F76: =AVERAGE(F5:F75) -> 91.628571 | G76: =AVERAGE(G5:G75) -> 38.027 | H76: =AVERAGE(H5:H75) -> 4.6654286

Sheet HMZ
C1: HAWAMAHAL - AMER ZONE
C2: URBAN ENVIRO WASTE MANAGEMENT D2D HOPPERS
C3: =TODAY() -> 46178
C4: SR NO. | D4: Ward | E4: VEHICLE REG. NO. | F4: COVERED % | G4: TOTAL DISTANCE | H4: Average Speed (KM/h) | I4: REMARKS
A5: MORNING_RJ14GN5224 | C5: 1 | D5: WARD 1 - WARD - 1 | E5: =VLOOKUP(A5,COV!$1:$1048576,2,0) -> RJ14GN5224 | F5: REPLACED BY 5214 (GPS TAMPERED)
A6: MORNING_RJ14GN7680 | C6: 2 | D6: WARD 1 - WARD - 1 | E6: =VLOOKUP(A6,COV!$1:$1048576,2,0) -> RJ14GN7680 | F6: =VLOOKUP(A6,COV!$1:$1048576,3,0) -> 91 | G6: =VLOOKUP(E6,DISTANCE!$1:$1048576,5,0) -> 59.13 | H6: =VLOOKUP(E6,DISTANCE!$1:$1048576,6,0) -> 3.77 | I6: =IF(F6<70,"DRIVER FAULT","")
A7: MORNING_RJ14GN7687 | C7: 3 | D7: WARD 2 - WARD - 2 | E7: =VLOOKUP(A7,COV!$1:$1048576,2,0) -> RJ14GN7687 | F7: =VLOOKUP(A7,COV!$1:$1048576,3,0) -> 95 | G7: =VLOOKUP(E7,DISTANCE!$1:$1048576,5,0) -> 32.63 | H7: =VLOOKUP(E7,DISTANCE!$1:$1048576,6,0) -> 3.44 | I7: =IF(F7<70,"DRIVER FAULT","")
A8: MORNING_RJ14GN7807 | C8: 4 | D8: WARD 2 - WARD - 2 | E8: =VLOOKUP(A8,COV!$1:$1048576,2,0) -> RJ14GN7807 | F8: =VLOOKUP(A8,COV!$1:$1048576,3,0) -> 93 | G8: =VLOOKUP(E8,DISTANCE!$1:$1048576,5,0) -> 53.53 | H8: =VLOOKUP(E8,DISTANCE!$1:$1048576,6,0) -> 7.39 | I8: =IF(F8<70,"DRIVER FAULT","")
A9: MORNING_RJ14GQ5280 | C9: 5 | D9: WARD 2 - WARD - 2 | E9: =VLOOKUP(A9,COV!$1:$1048576,2,0) -> RJ14GQ5280 | F9: =VLOOKUP(A9,COV!$1:$1048576,3,0) -> 90 | G9: =VLOOKUP(E9,DISTANCE!$1:$1048576,5,0) -> 82.27 | H9: =VLOOKUP(E9,DISTANCE!$1:$1048576,6,0) -> 11.27 | I9: =IF(F9<70,"DRIVER FAULT","")
A10: MORNING_RJ14GN7673 | C10: 6 | D10: WARD 3 - WARD - 3 | E10: =VLOOKUP(A10,COV!$1:$1048576,2,0) -> RJ14GN4991 | F10: =VLOOKUP(A10,COV!$1:$1048576,3,0) -> 75 | G10: =VLOOKUP(E10,DISTANCE!$1:$1048576,5,0) -> 28.32 | H10: =VLOOKUP(E10,DISTANCE!$1:$1048576,6,0) -> 6.9 | I10: =IF(F10<70,"DRIVER FAULT","")
A11: MORNING_RJ14GQ5291 | C11: 7 | D11: WARD 3 - WARD - 3 | E11: =VLOOKUP(A11,COV!$1:$1048576,2,0) -> RJ14GQ5291 | F11: =VLOOKUP(A11,COV!$1:$1048576,3,0) -> 100 | G11: =VLOOKUP(E11,DISTANCE!$1:$1048576,5,0) -> 35.67 | H11: =VLOOKUP(E11,DISTANCE!$1:$1048576,6,0) -> 2.26 | I11: =IF(F11<70,"DRIVER FAULT","")
A12: MORNING_RJ14GN5199 | C12: 8 | D12: WARD 3 - WARD - 3 | E12: =VLOOKUP(A12,COV!$1:$1048576,2,0) -> RJ14GN5034 | F12: =VLOOKUP(A12,COV!$1:$1048576,3,0) -> 85 | G12: =VLOOKUP(E12,DISTANCE!$1:$1048576,5,0) -> 33.42 | H12: =VLOOKUP(E12,DISTANCE!$1:$1048576,6,0) -> 9.91 | I12: =IF(F12<70,"DRIVER FAULT","")
A13: MORNING_RJ14GN7805 | C13: 9 | D13: WARD 3 - WARD - 3 | E13: =VLOOKUP(A13,COV!$1:$1048576,2,0) -> RJI4GN8483 | F13: =VLOOKUP(A13,COV!$1:$1048576,3,0) -> 89 | G13: =VLOOKUP(E13,DISTANCE!$1:$1048576,5,0) -> 55.87 | H13: =VLOOKUP(E13,DISTANCE!$1:$1048576,6,0) -> 8.97 | I13: =IF(F13<70,"DRIVER FAULT","")
A14: MORNING_RJ14GQ5288 | C14: 10 | D14: WARD 4 - WARD - 4 | E14: =VLOOKUP(A14,COV!$1:$1048576,2,0) -> RJ14GQ5288 | F14: =VLOOKUP(A14,COV!$1:$1048576,3,0) -> 92 | G14: =VLOOKUP(E14,DISTANCE!$1:$1048576,5,0) -> 54.67 | H14: =VLOOKUP(E14,DISTANCE!$1:$1048576,6,0) -> 6.64 | I14: =IF(F14<70,"DRIVER FAULT","")
A15: MORNING_RJ14GN7804 | C15: 11 | D15: WARD 4 - WARD - 4 | E15: =VLOOKUP(A15,COV!$1:$1048576,2,0) -> RJ14GN7804 | F15: REPLACED BY 6232 (GPS ISSUE)
A16: MORNING_RJ14GN7689 | C16: 12 | D16: WARD 4 - WARD - 4 | E16: =VLOOKUP(A16,COV!$1:$1048576,2,0) -> RJ14GN7689 | F16: =VLOOKUP(A16,COV!$1:$1048576,3,0) -> 96 | G16: =VLOOKUP(E16,DISTANCE!$1:$1048576,5,0) -> 29.16 | H16: =VLOOKUP(E16,DISTANCE!$1:$1048576,6,0) -> 8.33 | I16: =IF(F16<70,"DRIVER FAULT","")
A17: MORNING_RJ14GN7668 | C17: 13 | D17: WARD 5 - WARD - 5 | E17: =VLOOKUP(A17,COV!$1:$1048576,2,0) -> RJ14GN5753QT | F17: =VLOOKUP(A17,COV!$1:$1048576,3,0) -> 61 | G17: =VLOOKUP(E17,DISTANCE!$1:$1048576,5,0) -> 22.75 | H17: =VLOOKUP(E17,DISTANCE!$1:$1048576,6,0) -> 1.49 | I17: =IF(F17<70,"DRIVER FAULT","") -> DRIVER FAULT
A18: MORNING_RJ14GN7681 | C18: 14 | D18: WARD 6 - WARD - 6 | E18: =VLOOKUP(A18,COV!$1:$1048576,2,0) -> RJ14GN7681 | F18: =VLOOKUP(A18,COV!$1:$1048576,3,0) -> 93 | G18: =VLOOKUP(E18,DISTANCE!$1:$1048576,5,0) -> 36.75 | H18: =VLOOKUP(E18,DISTANCE!$1:$1048576,6,0) -> 5.25 | I18: =IF(F18<70,"DRIVER FAULT","")
A19: MORNING_RJ14GN7800 | C19: 15 | D19: WARD 6 - WARD - 6 | E19: =VLOOKUP(A19,COV!$1:$1048576,2,0) -> RJ14GN7800 | F19: =VLOOKUP(A19,COV!$1:$1048576,3,0) -> 78 | G19: =VLOOKUP(E19,DISTANCE!$1:$1048576,5,0) -> 35.03 | H19: =VLOOKUP(E19,DISTANCE!$1:$1048576,6,0) -> 4.03 | I19: =IF(F19<70,"DRIVER FAULT","")
A20: MORNING_RJ14GN7662 | C20: 16 | D20: WARD 7 - WARD - 7 | E20: =VLOOKUP(A20,COV!$1:$1048576,2,0) -> RJ14GN7662 | F20: =VLOOKUP(A20,COV!$1:$1048576,3,0) -> 93 | G20: =VLOOKUP(E20,DISTANCE!$1:$1048576,5,0) -> 22.58 | H20: =VLOOKUP(E20,DISTANCE!$1:$1048576,6,0) -> 4.04 | I20: =IF(F20<70,"DRIVER FAULT","")
A21: MORNING_RJ14GN7670 | C21: 17 | D21: WARD 7 - WARD - 7 | E21: =VLOOKUP(A21,COV!$1:$1048576,2,0) -> RJ14GN7670 | F21: =VLOOKUP(A21,COV!$1:$1048576,3,0) -> 100 | G21: =VLOOKUP(E21,DISTANCE!$1:$1048576,5,0) -> 64.52 | H21: =VLOOKUP(E21,DISTANCE!$1:$1048576,6,0) -> 7.34 | I21: =IF(F21<70,"DRIVER FAULT","")
A22: MORNING_RJ14GN7678 | C22: 18 | D22: WARD 8 - WARD - 8 | E22: =VLOOKUP(A22,COV!$1:$1048576,2,0) -> RJ14GN7678 | F22: =VLOOKUP(A22,COV!$1:$1048576,3,0) -> 91 | G22: =VLOOKUP(E22,DISTANCE!$1:$1048576,5,0) -> 39.18 | H22: =VLOOKUP(E22,DISTANCE!$1:$1048576,6,0) -> 6.61 | I22: =IF(F22<70,"DRIVER FAULT","")
A23: MORNING_RJ14GN7815 | C23: 19 | D23: WARD 8 - WARD - 8 | E23: =VLOOKUP(A23,COV!$1:$1048576,2,0) -> RJ14GN7815 | F23: =VLOOKUP(A23,COV!$1:$1048576,3,0) -> 86 | G23: =VLOOKUP(E23,DISTANCE!$1:$1048576,5,0) -> 33.71 | H23: =VLOOKUP(E23,DISTANCE!$1:$1048576,6,0) -> 6.35 | I23: =IF(F23<70,"DRIVER FAULT","")
A24: MORNING_RJ14GN7696 | C24: 20 | D24: WARD 9 - WARD - 9 | E24: =VLOOKUP(A24,COV!$1:$1048576,2,0) -> RJ14GN7696 | F24: =VLOOKUP(A24,COV!$1:$1048576,3,0) -> 84 | G24: =VLOOKUP(E24,DISTANCE!$1:$1048576,5,0) -> 34 | H24: =VLOOKUP(E24,DISTANCE!$1:$1048576,6,0) -> 5.05 | I24: =IF(F24<70,"DRIVER FAULT","")
A25: MORNING_RJ14GN7684 | C25: 21 | D25: WARD 9 - WARD - 9 | E25: =VLOOKUP(A25,COV!$1:$1048576,2,0) -> RJ14GN7684 | F25: =VLOOKUP(A25,COV!$1:$1048576,3,0) -> 93 | G25: =VLOOKUP(E25,DISTANCE!$1:$1048576,5,0) -> 35.95 | H25: =VLOOKUP(E25,DISTANCE!$1:$1048576,6,0) -> 5.6 | I25: =IF(F25<70,"DRIVER FAULT","")
A26: MORNING_RJ14GN8107 | C26: 22 | D26: WARD 10 - WARD - 10 | E26: =VLOOKUP(A26,COV!$1:$1048576,2,0) -> RJ14GN8107 | F26: =VLOOKUP(A26,COV!$1:$1048576,3,0) -> 88 | G26: =VLOOKUP(E26,DISTANCE!$1:$1048576,5,0) -> 25.72 | H26: =VLOOKUP(E26,DISTANCE!$1:$1048576,6,0) -> 6.07 | I26: =IF(F26<70,"DRIVER FAULT","")
A27: MORNING_RJ14GN7686 | C27: 23 | D27: WARD 10 - WARD - 10 | E27: =VLOOKUP(A27,COV!$1:$1048576,2,0) -> RJ14GN7686 | F27: =VLOOKUP(A27,COV!$1:$1048576,3,0) -> 85 | G27: =VLOOKUP(E27,DISTANCE!$1:$1048576,5,0) -> 43.69 | H27: =VLOOKUP(E27,DISTANCE!$1:$1048576,6,0) -> 6.29 | I27: =IF(F27<70,"DRIVER FAULT","")
... A53: MORNING_RJ14GN7695 | C53: 49 | D53: WARD 19 - WARD - 19 | E53: =VLOOKUP(A53,COV!$1:$1048576,2,0) -> RJ14GN7695 | F53: =VLOOKUP(A53,COV!$1:$1048576,3,0) -> 83 | G53: =VLOOKUP(E53,DISTANCE!$1:$1048576,5,0) -> 27.8 | H53: =VLOOKUP(E53,DISTANCE!$1:$1048576,6,0) -> 6.35 | I53: =IF(F53<70,"DRIVER FAULT","")
A54: MORNING_RJ14GQ5290 | C54: 50 | D54: WARD 20 - WARD - 20 | E54: =VLOOKUP(A54,COV!$1:$1048576,2,0) -> RJ14GQ5290 | F54: REPLACED BY 8471 (NOT WORKED)
A55: MORNING_RJ14GN7819 | C55: 51 | D55: WARD 20 - WARD - 20 | E55: =VLOOKUP(A55,COV!$1:$1048576,2,0) -> RJ14GN7819 | F55: =VLOOKUP(A55,COV!$1:$1048576,3,0) -> 90 | G55: =VLOOKUP(E55,DISTANCE!$1:$1048576,5,0) -> 23.58 | H55: =VLOOKUP(E55,DISTANCE!$1:$1048576,6,0) -> 3.4 | I55: =IF(F55<70,"DRIVER FAULT","")
A56: MORNING_RJ14GN7698 | C56: 52 | D56: WARD 20 - WARD - 20 | E56: =VLOOKUP(A56,COV!$1:$1048576,2,0) -> RJ14GN7698 | F56: =VLOOKUP(A56,COV!$1:$1048576,3,0) -> 92 | G56: =VLOOKUP(E56,DISTANCE!$1:$1048576,5,0) -> 44.61 | H56: =VLOOKUP(E56,DISTANCE!$1:$1048576,6,0) -> 9.57 | I56: =IF(F56<70,"DRIVER FAULT","")
A57: MORNING_RJ14GN7797 | C57: 53 | D57: WARD 21 - WARD - 21 | E57: =VLOOKUP(A57,COV!$1:$1048576,2,0) -> RJ14GN7797 | F57: =VLOOKUP(A57,COV!$1:$1048576,3,0) -> 92 | G57: =VLOOKUP(E57,DISTANCE!$1:$1048576,5,0) -> 29.16 | H57: =VLOOKUP(E57,DISTANCE!$1:$1048576,6,0) -> 6.06 | I57: =IF(F57<70,"DRIVER FAULT","")
A58: MORNING_RJ14GN7802 | C58: 54 | D58: WARD 21 - WARD - 21 | E58: =VLOOKUP(A58,COV!$1:$1048576,2,0) -> RJ14GN7802 | F58: =VLOOKUP(A58,COV!$1:$1048576,3,0) -> 92 | G58: =VLOOKUP(E58,DISTANCE!$1:$1048576,5,0) -> 36.11 | H58: =VLOOKUP(E58,DISTANCE!$1:$1048576,6,0) -> 5.66 | I58: =IF(F58<70,"DRIVER FAULT","")
A59: MORNING_RJ14GN7803 | C59: 55 | D59: WARD 22 - WARD - 22 | E59: =VLOOKUP(A59,COV!$1:$1048576,2,0) -> RJ14GN7803 | F59: =VLOOKUP(A59,COV!$1:$1048576,3,0) -> 95 | G59: =VLOOKUP(E59,DISTANCE!$1:$1048576,5,0) -> 24.65 | H59: =VLOOKUP(E59,DISTANCE!$1:$1048576,6,0) -> 5.05 | I59: =IF(F59<70,"DRIVER FAULT","")
A60: MORNING_RJ14GN7694 | C60: 56 | D60: WARD 22 - WARD - 22 | E60: =VLOOKUP(A60,COV!$1:$1048576,2,0) -> RJ14GN7694 | F60: =VLOOKUP(A60,COV!$1:$1048576,3,0) -> 90 | G60: =VLOOKUP(E60,DISTANCE!$1:$1048576,5,0) -> 22.58 | H60: =VLOOKUP(E60,DISTANCE!$1:$1048576,6,0) -> 5.14 | I60: =IF(F60<70,"DRIVER FAULT","")
A61: MORNING_RJ14GN7811 | C61: 57 | D61: WARD 23 - WARD - 23 | E61: =VLOOKUP(A61,COV!$1:$1048576,2,0) -> RJ14GN7811 | F61: =VLOOKUP(A61,COV!$1:$1048576,3,0) -> 95 | G61: =VLOOKUP(E61,DISTANCE!$1:$1048576,5,0) -> 45.41 | H61: =VLOOKUP(E61,DISTANCE!$1:$1048576,6,0) -> 6.21 | I61: =IF(F61<70,"DRIVER FAULT","")
A62: MORNING_RJ14GN7820 | C62: 58 | D62: WARD 23 - WARD - 23 | E62: =VLOOKUP(A62,COV!$1:$1048576,2,0) -> RJ14GN7820 | F62: =VLOOKUP(A62,COV!$1:$1048576,3,0) -> 100 | G62: =VLOOKUP(E62,DISTANCE!$1:$1048576,5,0) -> 43.16 | H62: =VLOOKUP(E62,DISTANCE!$1:$1048576,6,0) -> 7.61 | I62: =IF(F62<70,"DRIVER FAULT","")
A63: MORNING_RJ14GN7682 | C63: 59 | D63: WARD 24 - WARD - 24 | E63: =VLOOKUP(A63,COV!$1:$1048576,2,0) -> RJ14GN7682 | F63: =VLOOKUP(A63,COV!$1:$1048576,3,0) -> 89 | G63: =VLOOKUP(E63,DISTANCE!$1:$1048576,5,0) -> 27.99 | H63: =VLOOKUP(E63,DISTANCE!$1:$1048576,6,0) -> 3.21 | I63: =IF(F63<70,"DRIVER FAULT","")
A64: MORNING_RJ14GN7809 | C64: 60 | D64: WARD 24 - WARD - 24 | E64: =VLOOKUP(A64,COV!$1:$1048576,2,0) -> RJ14GN7809 | F64: =VLOOKUP(A64,COV!$1:$1048576,3,0) -> 84 | G64: =VLOOKUP(E64,DISTANCE!$1:$1048576,5,0) -> 37.69 | H64: =VLOOKUP(E64,DISTANCE!$1:$1048576,6,0) -> 7.03 | I64: =IF(F64<70,"DRIVER FAULT","")
A65: MORNING_RJ14GN7795 | C65: 61 | D65: WARD 25 - WARD - 25 | E65: =VLOOKUP(A65,COV!$1:$1048576,2,0) -> RJ14GN7795 | F65: =VLOOKUP(A65,COV!$1:$1048576,3,0) -> 91 | G65: =VLOOKUP(E65,DISTANCE!$1:$1048576,5,0) -> 37.83 | H65: =VLOOKUP(E65,DISTANCE!$1:$1048576,6,0) -> 5.91 | I65: =IF(F65<70,"DRIVER FAULT","")
...

Sheet SW
C2: HAWAMAHAL - AMER ZONE
C3: URBAN ENVIRO WASTE MANAGEMENT SWEEPING & DUSTBIN HOPPERS
C4: =TODAY() -> 46178
C5: SR NO. | D5: Ward | E5: VEHICLE REG. NO. | F5: Start Time | G5: End Time | H5: Active Hours | I5: Total Distance (KM) | J5: Average Speed (KM/h) | K5: REMARKS
A6: SWEEPING_RJ14GN5034SW | C6: 1 | D6: Ward 1 - Ward - 1 | E6: =VLOOKUP(A6,COV!$1:$1048576,2,0) -> RJ14GN5199SW | F6: =VLOOKUP(E6,DISTANCE!$1:$1048576,2,0) -> 0.28472222 | G6: =VLOOKUP(E6,DISTANCE!$1:$1048576,3,0) -> 0.49722222 | H6: =VLOOKUP(E6,DISTANCE!$1:$1048576,4,0) -> 0.21231481 | I6: =VLOOKUP(E6,DISTANCE!$1:$1048576,5,0) -> 44.65 | J6: =VLOOKUP(E6,DISTANCE!$1:$1048576,6,0) -> 8.76 | K6: =IF(I6<8,"NOT WORKED","")
A7: SWEEPING_W2_RJ14GQ5284 | C7: 2 | D7: Ward 2 - Ward - 2 | E7: =VLOOKUP(A7,COV!$1:$1048576,2,0) -> RJ14GQ5284SW | F7: =VLOOKUP(E7,DISTANCE!$1:$1048576,2,0) -> 0.29305556 | G7: =VLOOKUP(E7,DISTANCE!$1:$1048576,3,0) -> 0.42430556 | H7: =VLOOKUP(E7,DISTANCE!$1:$1048576,4,0) -> 0.13115741 | I7: =VLOOKUP(E7,DISTANCE!$1:$1048576,5,0) -> 37.55 | J7: =VLOOKUP(E7,DISTANCE!$1:$1048576,6,0) -> 11.93 | K7: =IF(I7<8,"NOT WORKED","")
A8: SWEEPING_W3_RJ14GN5750 | C8: 3 | D8: Ward 3 - Ward - 3 | E8: =VLOOKUP(A8,COV!$1:$1048576,2,0) -> RJ14GN5750SW | F8: =VLOOKUP(E8,DISTANCE!$1:$1048576,2,0) -> 0.26875 | G8: =VLOOKUP(E8,DISTANCE!$1:$1048576,3,0) -> 0.39583333 | H8: =VLOOKUP(E8,DISTANCE!$1:$1048576,4,0) -> 0.12653935 | I8: =VLOOKUP(E8,DISTANCE!$1:$1048576,5,0) -> 17.65 | J8: =VLOOKUP(E8,DISTANCE!$1:$1048576,6,0) -> 5.81 | K8: =IF(I8<8,"NOT WORKED","")
A9: SWEEPING_W4_RJ14GQ5303 | C9: 4 | D9: Ward 4 - Ward - 4 | E9: =VLOOKUP(A9,COV!$1:$1048576,2,0) -> RJ14GQ5303SW | F9: =VLOOKUP(E9,DISTANCE!$1:$1048576,2,0) -> 0.29583333 | G9: =VLOOKUP(E9,DISTANCE!$1:$1048576,3,0) -> 0.63888889 | H9: =VLOOKUP(E9,DISTANCE!$1:$1048576,4,0) -> 0.34278935 | I9: =VLOOKUP(E9,DISTANCE!$1:$1048576,5,0) -> 10.95 | J9: =VLOOKUP(E9,DISTANCE!$1:$1048576,6,0) -> 1.33 | K9: =IF(I9<8,"NOT WORKED","")
A10: SWEEPING_RJ14GN5195SW | C10: 5 | D10: Ward 5 - Ward - 5 | E10: =VLOOKUP(A10,COV!$1:$1048576,2,0) -> RJ14GN5598SW | F10: =VLOOKUP(E10,DISTANCE!$1:$1048576,2,0) -> 0.22708333 | G10: =VLOOKUP(E10,DISTANCE!$1:$1048576,3,0) -> 0.52569444 | H10: =VLOOKUP(E10,DISTANCE!$1:$1048576,4,0) -> 0.29828704 | I10: =VLOOKUP(E10,DISTANCE!$1:$1048576,5,0) -> 14.84 | J10: =VLOOKUP(E10,DISTANCE!$1:$1048576,6,0) -> 2.07 | K10: =IF(I10<8,"NOT WORKED","")
A11: SWEEPING_RJ14GN5970SW | C11: 6 | D11: Ward 6 - Ward - 6 | E11: =VLOOKUP(A11,COV!$1:$1048576,2,0) -> RJ14GQ5274SW | F11: =VLOOKUP(E11,DISTANCE!$1:$1048576,2,0) -> 0.29722222 | G11: =VLOOKUP(E11,DISTANCE!$1:$1048576,3,0) -> 0.50902778 | H11: =VLOOKUP(E11,DISTANCE!$1:$1048576,4,0) -> 0.2122338 | I11: =VLOOKUP(E11,DISTANCE!$1:$1048576,5,0) -> 20.85 | J11: =VLOOKUP(E11,DISTANCE!$1:$1048576,6,0) -> 4.09 | K11: =IF(I11<8,"NOT WORKED","")
A12: SWEEPING_W7_RJ14GN8553 | C12: 7 | D12: Ward 7 - Ward - 7 | E12: =VLOOKUP(A12,COV!$1:$1048576,2,0) -> RJ14GN5296SW | F12: =VLOOKUP(E12,DISTANCE!$1:$1048576,2,0) -> 0.325 | G12: =VLOOKUP(E12,DISTANCE!$1:$1048576,3,0) -> 0.4875 | H12: =VLOOKUP(E12,DISTANCE!$1:$1048576,4,0) -> 0.16251157 | I12: =VLOOKUP(E12,DISTANCE!$1:$1048576,5,0) -> 24.04 | J12: =VLOOKUP(E12,DISTANCE!$1:$1048576,6,0) -> 6.16 | K12: =IF(I12<8,"NOT WORKED","")
A13: SWEEPING_RJ14GN5031SW | C13: 8 | D13: Ward 8 - Ward - 8 | E13: =VLOOKUP(A13,COV!$1:$1048576,2,0) -> RJ14GN5031SW | F13: =VLOOKUP(E13,DISTANCE!$1:$1048576,2,0) -> 0.27916667 | G13: =VLOOKUP(E13,DISTANCE!$1:$1048576,3,0) -> 0.49375 | H13: =VLOOKUP(E13,DISTANCE!$1:$1048576,4,0) -> 0.21434028 | I13: =VLOOKUP(E13,DISTANCE!$1:$1048576,5,0) -> 16.66 | J13: =VLOOKUP(E13,DISTANCE!$1:$1048576,6,0) -> 3.24 | K13: =IF(I13<8,"NOT WORKED","")
A14: SWEEPING_RJ14GN5740 | C14: 9 | D14: Ward 8 - Ward - 8 | E14: =VLOOKUP(A14,COV!$1:$1048576,2,0) -> RJ14GN5740SW | F14: =VLOOKUP(E14,DISTANCE!$1:$1048576,2,0) -> 0.28958333 | G14: =VLOOKUP(E14,DISTANCE!$1:$1048576,3,0) -> 0.49236111 | H14: =VLOOKUP(E14,DISTANCE!$1:$1048576,4,0) -> 0.20224537 | I14: =VLOOKUP(E14,DISTANCE!$1:$1048576,5,0) -> 24.93 | J14: =VLOOKUP(E14,DISTANCE!$1:$1048576,6,0) -> 5.14 | K14: =IF(I14<8,"NOT WORKED","")
A15: SWEEPING_RJ14GN5212SW | C15: 10 | D15: Ward 9 - Ward - 9 | E15: =VLOOKUP(A15,COV!$1:$1048576,2,0) -> RJ14GN5212SW | F15: =VLOOKUP(E15,DISTANCE!$1:$1048576,2,0) -> 0.28402778 | G15: =VLOOKUP(E15,DISTANCE!$1:$1048576,3,0) -> 0.49027778 | H15: =VLOOKUP(E15,DISTANCE!$1:$1048576,4,0) -> 0.20592593 | I15: =VLOOKUP(E15,DISTANCE!$1:$1048576,5,0) -> 25.7 | J15: =VLOOKUP(E15,DISTANCE!$1:$1048576,6,0) -> 5.2 | K15: =IF(I15<8,"NOT WORKED","")
A16: SWEEPING_RJ14GN4983SW | C16: 11 | D16: Ward 9 - Ward - 9 | E16: =VLOOKUP(A16,COV!$1:$1048576,2,0) -> RJ14GN4983SW | F16: =VLOOKUP(E16,DISTANCE!$1:$1048576,2,0) -> 0.29444444 | G16: =VLOOKUP(E16,DISTANCE!$1:$1048576,3,0) -> 0.55138889 | H16: =VLOOKUP(E16,DISTANCE!$1:$1048576,4,0) -> 0.25655093 | I16: =VLOOKUP(E16,DISTANCE!$1:$1048576,5,0) -> 29.22 | J16: =VLOOKUP(E16,DISTANCE!$1:$1048576,6,0) -> 4.75 | K16: =IF(I16<8,"NOT WORKED","")
A17: SWEEPING_W10_RJ14GN5740SW | C17: 12 | D17: Ward 10 - Ward - 10 | E17: =VLOOKUP(A17,COV!$1:$1048576,2,0) -> RJ14GQ5279SW | F17: =VLOOKUP(E17,DISTANCE!$1:$1048576,2,0) -> 0.27986111 | G17: =VLOOKUP(E17,DISTANCE!$1:$1048576,3,0) -> 0.51180556 | H17: =VLOOKUP(E17,DISTANCE!$1:$1048576,4,0) -> 0.23193287 | I17: =VLOOKUP(E17,DISTANCE!$1:$1048576,5,0) -> 17.35 | J17: =VLOOKUP(E17,DISTANCE!$1:$1048576,6,0) -> 3.12 | K17: =IF(I17<8,"NOT WORKED","")
... A47: SWEEPING_W27_RJ14GN5214 | C47: 42 | D47: Ward 27 - Ward - 27 | E47: =VLOOKUP(A47,COV!$1:$1048576,2,0) -> RJ14GN4980SW | F47: =VLOOKUP(E47,DISTANCE!$1:$1048576,2,0) -> 0.31736111 | G47: =VLOOKUP(E47,DISTANCE!$1:$1048576,3,0) -> 0.48958333 | H47: =VLOOKUP(E47,DISTANCE!$1:$1048576,4,0) -> 0.17185185 | I47: =VLOOKUP(E47,DISTANCE!$1:$1048576,5,0) -> 19.58 | J47: =VLOOKUP(E47,DISTANCE!$1:$1048576,6,0) -> 4.75 | K47: =IF(I47<8,"NOT WORKED","")
A48: SWEEPING_RJ14GN5287SW | C48: 43 | D48: Ward 28 - Ward - 28 | E48: =VLOOKUP(A48,COV!$1:$1048576,2,0) -> RJ14GN5967SW | F48: NETWORK ISSUE
A49: SW_W29_RJ14GN5202SW | C49: 44 | D49: Ward 29 - Ward - 29 | E49: =VLOOKUP(A49,COV!$1:$1048576,2,0) -> RJ14GN5202SW | F49: =VLOOKUP(E49,DISTANCE!$1:$1048576,2,0) -> 0.30972222 | G49: =VLOOKUP(E49,DISTANCE!$1:$1048576,3,0) -> 0.51111111 | H49: =VLOOKUP(E49,DISTANCE!$1:$1048576,4,0) -> 0.20170139 | I49: =VLOOKUP(E49,DISTANCE!$1:$1048576,5,0) -> 13.26 | J49: =VLOOKUP(E49,DISTANCE!$1:$1048576,6,0) -> 2.74 | K49: =IF(I49<8,"NOT WORKED","")
A50: SWEEPING_RJ14GN6232SW | C50: 45 | D50: Ward 30 - Ward - 30 | E50: =VLOOKUP(A50,COV!$1:$1048576,2,0) -> RJ14GQ5272SW | F50: =VLOOKUP(E50,DISTANCE!$1:$1048576,2,0) -> 0.097222222 | G50: =VLOOKUP(E50,DISTANCE!$1:$1048576,3,0) -> 0.58333333 | H50: =VLOOKUP(E50,DISTANCE!$1:$1048576,4,0) -> 0.48600694 | I50: =VLOOKUP(E50,DISTANCE!$1:$1048576,5,0) -> 38.29 | J50: =VLOOKUP(E50,DISTANCE!$1:$1048576,6,0) -> 3.28 | K50: =IF(I50<8,"NOT WORKED","")
C51: AVERAGE | I51: =AVERAGE(I6:I50) -> 25.817273 | J51: =AVERAGE(J6:J50) -> 4.6225
C53: CIVIL LINES ZONE
C54: WEVOIS LABS PVT LTD. SWEEPING HOPPERS
C55: =TODAY() -> 46178
C56: SR NO. | D56: Ward | E56: VEHICLE REG. NO. | F56: Start Time | G56: End Time | H56: Active Hours | I56: Total Distance (KM) | J56: Average Speed (KM/h) | K56: REMARKS
A57: W31_SVD11423SW | C57: 1 | D57: Ward 31 - Ward - 31 | E57: =VLOOKUP(A57,COV!$1:$1048576,2,0) -> RJ14GT8837SW | F57: =VLOOKUP(E57,DISTANCE!$1:$1048576,2,0) -> 0.28611111 | G57: =VLOOKUP(E57,DISTANCE!$1:$1048576,3,0) -> 0.5 | H57: =VLOOKUP(E57,DISTANCE!$1:$1048576,4,0) -> 0.21362269 | I57: =VLOOKUP(E57,DISTANCE!$1:$1048576,5,0) -> 9.8 | J57: =VLOOKUP(E57,DISTANCE!$1:$1048576,6,0) -> 1.91 | K57: =IF(I57<8,"NOT WORKED","")
A58: W32_SVC08958SW | C58: 2 | D58: Ward 32 - Ward - 32 | E58: =VLOOKUP(A58,COV!$1:$1048576,2,0) -> RJ14GT8839SW | F58: =VLOOKUP(E58,DISTANCE!$1:$1048576,2,0) -> 0.32291667 | G58: =VLOOKUP(E58,DISTANCE!$1:$1048576,3,0) -> 0.46458333 | H58: =VLOOKUP(E58,DISTANCE!$1:$1048576,4,0) -> 0.14131944 | I58: =VLOOKUP(E58,DISTANCE!$1:$1048576,5,0) -> 12.63 | J58: =VLOOKUP(E58,DISTANCE!$1:$1048576,6,0) -> 3.72 | K58: =IF(I58<8,"NOT WORKED","")
A59: W33_SVC09135SW | C59: 3 | D59: Ward 33 - Ward - 33 | E59: =VLOOKUP(A59,COV!$1:$1048576,2,0) -> RJ14GT8239SW | F59: NOT WORKED
A60: W34_SVD11271SW | C60: 4 | D60: Ward 34 - Ward - 34 | E60: =VLOOKUP(A60,COV!$1:$1048576,2,0) -> RJ14GT8286SW | F60: =VLOOKUP(E60,DISTANCE!$1:$1048576,2,0) -> 0.27638889 | G60: =VLOOKUP(E60,DISTANCE!$1:$1048576,3,0) -> 0.59791667 | H60: =VLOOKUP(E60,DISTANCE!$1:$1048576,4,0) -> 0.32175926 | I60: =VLOOKUP(E60,DISTANCE!$1:$1048576,5,0) -> 34.21 | J60: =VLOOKUP(E60,DISTANCE!$1:$1048576,6,0) -> 4.43 | K60: =IF(I60<8,"NOT WORKED","")
A61: W35_SVE16701SW_R1 | C61: 5 | D61: Ward 35 - Ward - 35 | E61: =VLOOKUP(A61,COV!$1:$1048576,2,0) -> SVE16701SW | F61: =VLOOKUP(E61,DISTANCE!$1:$1048576,2,0) -> 0.30625 | G61: =VLOOKUP(E61,DISTANCE!$1:$1048576,3,0) -> 0.61388889 | H61: =VLOOKUP(E61,DISTANCE!$1:$1048576,4,0) -> 0.3078125 | I61: =VLOOKUP(E61,DISTANCE!$1:$1048576,5,0) -> 21.42 | J61: =VLOOKUP(E61,DISTANCE!$1:$1048576,6,0) -> 2.9 | K61: =IF(I61<8,"NOT WORKED","")
A62: W35_SVE14993SW_R2 | C62: 6 | D62: Ward 35 - Ward - 35 | E62: =VLOOKUP(A62,COV!$1:$1048576,2,0) -> RJ14GT8907SW | F62: =VLOOKUP(E62,DISTANCE!$1:$1048576,2,0) -> 0.31458333 | G62: =VLOOKUP(E62,DISTANCE!$1:$1048576,3,0) -> 0.56944444 | H62: =VLOOKUP(E62,DISTANCE!$1:$1048576,4,0) -> 0.25545139 | I62: =VLOOKUP(E62,DISTANCE!$1:$1048576,5,0) -> 26.13 | J62: =VLOOKUP(E62,DISTANCE!$1:$1048576,6,0) -> 4.26 | K62: =IF(I62<8,"NOT WORKED","")
A63: W36_SVE14915SW_R1 | C63: 7 | D63: Ward 36 - Ward - 36 | E63: =VLOOKUP(A63,COV!$1:$1048576,2,0) -> RJ14GT8937SW | F63: =VLOOKUP(E63,DISTANCE!$1:$1048576,2,0) -> 0.28680556 | G63: =VLOOKUP(E63,DISTANCE!$1:$1048576,3,0) -> 0.52569444 | H63: =VLOOKUP(E63,DISTANCE!$1:$1048576,4,0) -> 0.23883102 | I63: =VLOOKUP(E63,DISTANCE!$1:$1048576,5,0) -> 23.63 | J63: =VLOOKUP(E63,DISTANCE!$1:$1048576,6,0) -> 4.12 | K63: =IF(I63<8,"NOT WORKED","")
A64: W36_SVD11722SW_R2 | C64: 8 | D64: Ward 36 - Ward - 36 | E64: =VLOOKUP(A64,COV!$1:$1048576,2,0) -> RJ14GT8847SW | F64: GPS TAMPERED
A65: W37_SVD10996SW | C65: 9 | D65: Ward 37 - Ward - 37 | E65: =VLOOKUP(A65,COV!$1:$1048576,2,0) -> RJ14GT7542SW | F65: =VLOOKUP(E65,DISTANCE!$1:$1048576,2,0) -> 0.30277778 | G65: =VLOOKUP(E65,DISTANCE!$1:$1048576,3,0) -> 0.56736111 | H65: =VLOOKUP(E65,DISTANCE!$1:$1048576,4,0) -> 0.26438657 | I65: =VLOOKUP(E65,DISTANCE!$1:$1048576,5,0) -> 21.45 | J65: =VLOOKUP(E65,DISTANCE!$1:$1048576,6,0) -> 3.38 | K65: =IF(I65<8,"NOT WORKED","")
A66: W38_SVC09056SW | C66: 10 | D66: Ward 38 - Ward - 38 | E66: =VLOOKUP(A66,COV!$1:$1048576,2,0) -> RJ14GT7569SW | F66: =VLOOKUP(E66,DISTANCE!$1:$1048576,2,0) -> 0.30902778 | G66: =VLOOKUP(E66,DISTANCE!$1:$1048576,3,0) -> 0.44305556 | H66: =VLOOKUP(E66,DISTANCE!$1:$1048576,4,0) -> 0.13364583 | I66: =VLOOKUP(E66,DISTANCE!$1:$1048576,5,0) -> 11.66 | J66: =VLOOKUP(E66,DISTANCE!$1:$1048576,6,0) -> 3.64 | K66: =IF(I66<8,"NOT WORKED","")
A67: W39_SVD11055SW | C67: 11 | D67: Ward 39 - Ward - 39 | E67: =VLOOKUP(A67,COV!$1:$1048576,2,0) -> RJ14GT7546SW | F67: =VLOOKUP(E67,DISTANCE!$1:$1048576,2,0) -> 0.28263889 | G67: =VLOOKUP(E67,DISTANCE!$1:$1048576,3,0) -> 0.61180556 | H67: =VLOOKUP(E67,DISTANCE!$1:$1048576,4,0) -> 0.32935185 | I67: =VLOOKUP(E67,DISTANCE!$1:$1048576,5,0) -> 39.33 | J67: =VLOOKUP(E67,DISTANCE!$1:$1048576,6,0) -> 4.98 | K67: =IF(I67<8,"NOT WORKED","")
A68: W40_SZE13106SW | C68: 12 | D68: Ward 40 - Ward - 40 | E68: =VLOOKUP(A68,COV!$1:$1048576,2,0) -> RJ14GT8163SW | F68: =VLOOKUP(E68,DISTANCE!$1:$1048576,2,0) -> 0.27083333 | G68: =VLOOKUP(E68,DISTANCE!$1:$1048576,3,0) -> 0.56944444 | H68: =VLOOKUP(E68,DISTANCE!$1:$1048576,4,0) -> 0.29863426 | I68: =VLOOKUP(E68,DISTANCE!$1:$1048576,5,0) -> 20.56 | J68: =VLOOKUP(E68,DISTANCE!$1:$1048576,6,0) -> 2.87 | K68: =IF(I68<8,"NOT WORKED","")
A69: W41_SVD11447SW | C69: 13 | D69: Ward 41 - Ward - 41 | E69: =VLOOKUP(A69,COV!$1:$1048576,2,0) -> RJ14GT8168SW | F69: =VLOOKUP(E69,DISTANCE!$1:$1048576,2,0) -> 0.30972222 | G69: =VLOOKUP(E69,DISTANCE!$1:$1048576,3,0) -> 0.50555556 | H69: =VLOOKUP(E69,DISTANCE!$1:$1048576,4,0) -> 0.19616898 | I69: =VLOOKUP(E69,DISTANCE!$1:$1048576,5,0) -> 21.51 | J69: =VLOOKUP(E69,DISTANCE!$1:$1048576,6,0) -> 4.57 | K69: =IF(I69<8,"NOT WORKED","")
A70: W42_SVD11281SW | C70: 14 | D70: Ward 42 - Ward - 42 | E70: =VLOOKUP(A70,COV!$1:$1048576,2,0) -> RJ14GT7568SW | F70: =VLOOKUP(E70,DISTANCE!$1:$1048576,2,0) -> 0.27777778 | G70: =VLOOKUP(E70,DISTANCE!$1:$1048576,3,0) -> 0.6375 | H70: =VLOOKUP(E70,DISTANCE!$1:$1048576,4,0) -> 0.35971065 | I70: =VLOOKUP(E70,DISTANCE!$1:$1048576,5,0) -> 53.99 | J70: =VLOOKUP(E70,DISTANCE!$1:$1048576,6,0) -> 6.25 | K70: =IF(I70<8,"NOT WORKED","")
A71: W43_SVE15827SW | C71: 15 | D71: Ward 43 - Ward - 43 | E71: =VLOOKUP(A71,COV!$1:$1048576,2,0) -> SVE15827SW | F71: =VLOOKUP(E71,DISTANCE!$1:$1048576,2,0) -> 0.30138889 | G71: =VLOOKUP(E71,DISTANCE!$1:$1048576,3,0) -> 0.51111111 | H71: =VLOOKUP(E71,DISTANCE!$1:$1048576,4,0) -> 0.21012731 | I71: =VLOOKUP(E71,DISTANCE!$1:$1048576,5,0) -> 34.46 | J71: =VLOOKUP(E71,DISTANCE!$1:$1048576,6,0) -> 6.83 | K71: =IF(I71<8,"NOT WORKED","")
...

Sheet SUM
B2: NAGAR NIGAM JAIPUR PART - II
B3: ALL ZONES DOOR TO DOOR HOPPERS (07:00 AM TO 03:30 PM )
B4: =TODAY() -> 46178
B5: SR NO. | C5: ZONE | D5: NO. OF D2D HOPPERS | E5: NO. OF NOT WORKED HOPPERS | F5: COVERED % | G5: Total Distance (KM) | H5: TRIPS
B6: 1 | C6: HAWAMAHAL - AMER ZONE | D6: 81 | E6: =COUNTIF(HMZ!F5:I86,"NOT WORKED") -> 0 | F6: =HMZ!F86 -> 90.733333 | G6: =HMZ!G86 -> 36.1844 | H6: 164
B7: 2 | C7: CIVIL LINES ZONE | D7: 71 | E7: =COUNTIF(CLZ!E5:I75,"NOT WORKED") -> 0 | F7: =CLZ!F76 -> 91.628571 | G7: =CLZ!G76 -> 38.027 | H7: 203
B8: 3 | C8: KISHANPOLE ZONE | D8: 42 | E8: =COUNTIF(KPZ!F5:I46,"NOT WORKED") -> 0 | F8: =KPZ!F47 -> 91.219512 | G8: =KPZ!G47 -> 23.302439 | H8: 98
B9: 4 | C9: ADARSH NAGAR ZONE | D9: 65 | E9: =COUNTIF(ANZ!F5:I69,"NOT WORKED") -> 1 | F9: =ANZ!F70 -> 89.854839 | G9: =ANZ!G70 -> 31.363226 | H9: 161
B10: AVERAGE/TOTAL | D10: =SUM(D6:D9) -> 259 | E10: =SUM(E6:E9) -> 1 | F10: =CONCATENATE(ROUND(AVERAGE(F6:F9),2),"%") -> 90.86% | G10: =CONCATENATE(ROUND(AVERAGE(G6:G9),2),"KM") -> 32.22KM | H10: =SUM(H6:H9) -> 626
B12: ALL ZONES STREET SWEEPING HOPPERS
B13: SR NO. | C13: ZONE | D13: NO. OF SWEEPING HOPPERS | E13: NO. OF NOT WORKED HOPPERS | G13: Total Distance (KM) | H13: TRIPS
B14: 1 | C14: HAWAMAHAL - AMER ZONE | D14: 45 | E14: =COUNTIF(SW!F6:K50,"NOT WORKED") -> 0 | G14: =SW!I51 -> 25.817273 | H14: 58
B15: 2 | C15: CIVIL LINES ZONE | D15: 34 | E15: =COUNTIF(SW!F57:K90,"NOT WORKED") -> 2 | G15: =SW!I91 -> 27.992903 | H15: 47
B16: 3 | C16: KISHANPOLE ZONE | D16: 51 | E16: =COUNTIF(SW!F97:K147,"NOT WORKED") -> 2 | G16: =SW!I148 -> 22.262128 | H16: 71
B17: 4 | C17: ADARSH NAGAR ZONE | D17: 45 | E17: =COUNTIF(SW!F154:K198,"NOT WORKED") -> 2 | G17: =SW!I199 -> 29.52907 | H17: 65
B18: AVERAGE/TOTAL | D18: =SUM(D14:D17) -> 175 | E18: =SUM(E14:F17) -> 6 | G18: =CONCATENATE(ROUND(AVERAGE(G14:G17),2),"KM") -> 26.4KM | H18: =SUM(H14:H17) -> 241
B20: ALL ZONES EVENING COMMERCIAL HOPPERS ( 04:00PM TO 11:00 PM)
B21: =TODAY()-1 -> 46177
B22: SR NO. | C22: ZONE | D22: NO. OF HOPPERS | E22: NO. OF NOT WORKED HOPPERS | G22: Total Distance (KM) | H22: TRIPS
B23: 1 | C23: HAWAMAHAL - AMER ZONE
B24: 2 | C24: CIVIL LINES ZONE
B25: 3 | C25: KISHANPOLE ZONE
B26: 4 | C26: ADARSH NAGAR ZONE
B27: AVERAGE/TOTAL | D27: =SUM(D23:D26) -> 0 | E27: =SUM(E23:F26) -> 0 | G27: =CONCATENATE(ROUND(AVERAGE(G23:G26),2),"KM") -> #DIV/0! | H27: 70

Sheet DEPARTED
A1: MORNING_RJ14GN5224 | B1: 1 | C1: Zone 1 - Hawa Mahal-Aamer Zone | D1: WARD 1 - WARD - 1 | E1: =VLOOKUP(A1,COV!$1:$1048576,2,0) -> RJ14GN5224 | F1: =VLOOKUP(E1,DISTANCE!$1:$1048576,2,0) -> 0.65833333 | G1: =VLOOKUP(E1,DISTANCE!$1:$1048576,3,0) -> 0.65833333 | H1: =VLOOKUP(E1,DISTANCE!$1:$1048576,4,0) -> 0 | I1: =VLOOKUP(E1,DISTANCE!$1:$1048576,5,0) -> 0
A2: MORNING_RJ14GN7680 | B2: 2 | C2: Zone 1 - Hawa Mahal-Aamer Zone | D2: WARD 1 - WARD - 1 | E2: =VLOOKUP(A2,COV!$1:$1048576,2,0) -> RJ14GN7680 | F2: =VLOOKUP(E2,DISTANCE!$1:$1048576,2,0) -> 0.00625 | G2: =VLOOKUP(E2,DISTANCE!$1:$1048576,3,0) -> 0.66041667 | H2: =VLOOKUP(E2,DISTANCE!$1:$1048576,4,0) -> 0.6540625 | I2: =VLOOKUP(E2,DISTANCE!$1:$1048576,5,0) -> 59.13
A3: MORNING_RJ14GN7687 | B3: 3 | C3: Zone 1 - Hawa Mahal-Aamer Zone | D3: WARD 2 - WARD - 2 | E3: =VLOOKUP(A3,COV!$1:$1048576,2,0) -> RJ14GN7687 | F3: =VLOOKUP(E3,DISTANCE!$1:$1048576,2,0) -> 0.25486111 | G3: =VLOOKUP(E3,DISTANCE!$1:$1048576,3,0) -> 0.65 | H3: =VLOOKUP(E3,DISTANCE!$1:$1048576,4,0) -> 0.39491898 | I3: =VLOOKUP(E3,DISTANCE!$1:$1048576,5,0) -> 32.63
A4: MORNING_RJ14GN7807 | B4: 4 | C4: Zone 1 - Hawa Mahal-Aamer Zone | D4: WARD 2 - WARD - 2 | E4: =VLOOKUP(A4,COV!$1:$1048576,2,0) -> RJ14GN7807 | F4: =VLOOKUP(E4,DISTANCE!$1:$1048576,2,0) -> 0.28402778 | G4: =VLOOKUP(E4,DISTANCE!$1:$1048576,3,0) -> 0.58611111 | H4: =VLOOKUP(E4,DISTANCE!$1:$1048576,4,0) -> 0.30174769 | I4: =VLOOKUP(E4,DISTANCE!$1:$1048576,5,0) -> 53.53
A5: MORNING_RJ14GQ5280 | B5: 5 | C5: Zone 1 - Hawa Mahal-Aamer Zone | D5: WARD 2 - WARD - 2 | E5: =VLOOKUP(A5,COV!$1:$1048576,2,0) -> RJ14GQ5280 | F5: =VLOOKUP(E5,DISTANCE!$1:$1048576,2,0) -> 0.27152778 | G5: =VLOOKUP(E5,DISTANCE!$1:$1048576,3,0) -> 0.57569444 | H5: =VLOOKUP(E5,DISTANCE!$1:$1048576,4,0) -> 0.30408565 | I5: =VLOOKUP(E5,DISTANCE!$1:$1048576,5,0) -> 82.27
A6: MORNING_RJ14GN7673 | B6: 6 | C6: Zone 1 - Hawa Mahal-Aamer Zone | D6: WARD 3 - WARD - 3 | E6: =VLOOKUP(A6,COV!$1:$1048576,2,0) -> RJ14GN4991 | F6: =VLOOKUP(E6,DISTANCE!$1:$1048576,2,0) -> 0.27777778 | G6: =VLOOKUP(E6,DISTANCE!$1:$1048576,3,0) -> 0.44930556 | H6: =VLOOKUP(E6,DISTANCE!$1:$1048576,4,0) -> 0.17097222 | I6: =VLOOKUP(E6,DISTANCE!$1:$1048576,5,0) -> 28.32
A7: MORNING_RJ14GQ5291 | B7: 7 | C7: Zone 1 - Hawa Mahal-Aamer Zone | D7: WARD 3 - WARD - 3 | E7: =VLOOKUP(A7,COV!$1:$1048576,2,0) -> RJ14GQ5291 | F7: =VLOOKUP(E7,DISTANCE!$1:$1048576,2,0) -> 0.0034722222 | G7: =VLOOKUP(E7,DISTANCE!$1:$1048576,3,0) -> 0.66180556 | H7: =VLOOKUP(E7,DISTANCE!$1:$1048576,4,0) -> 0.65834491 | I7: =VLOOKUP(E7,DISTANCE!$1:$1048576,5,0) -> 35.67
A8: MORNING_RJ14GN5199 | B8: 8 | C8: Zone 1 - Hawa Mahal-Aamer Zone | D8: WARD 3 - WARD - 3 | E8: =VLOOKUP(A8,COV!$1:$1048576,2,0) -> RJ14GN5034 | F8: =VLOOKUP(E8,DISTANCE!$1:$1048576,2,0) -> 0.30347222 | G8: =VLOOKUP(E8,DISTANCE!$1:$1048576,3,0) -> 0.44375 | H8: =VLOOKUP(E8,DISTANCE!$1:$1048576,4,0) -> 0.14047454 | I8: =VLOOKUP(E8,DISTANCE!$1:$1048576,5,0) -> 33.42
A9: MORNING_RJ14GN7805 | B9: 9 | C9: Zone 1 - Hawa Mahal-Aamer Zone | D9: WARD 3 - WARD - 3 | E9: =VLOOKUP(A9,COV!$1:$1048576,2,0) -> RJI4GN8483 | F9: =VLOOKUP(E9,DISTANCE!$1:$1048576,2,0) -> 0.27222222 | G9: =VLOOKUP(E9,DISTANCE!$1:$1048576,3,0) -> 0.53194444 | H9: =VLOOKUP(E9,DISTANCE!$1:$1048576,4,0) -> 0.25953704 | I9: =VLOOKUP(E9,DISTANCE!$1:$1048576,5,0) -> 55.87
A10: MORNING_RJ14GQ5288 | B10: 10 | C10: Zone 1 - Hawa Mahal-Aamer Zone | D10: WARD 4 - WARD - 4 | E10: =VLOOKUP(A10,COV!$1:$1048576,2,0) -> RJ14GQ5288 | F10: =VLOOKUP(E10,DISTANCE!$1:$1048576,2,0) -> 0.26111111 | G10: =VLOOKUP(E10,DISTANCE!$1:$1048576,3,0) -> 0.60416667 | H10: =VLOOKUP(E10,DISTANCE!$1:$1048576,4,0) -> 0.34322917 | I10: =VLOOKUP(E10,DISTANCE!$1:$1048576,5,0) -> 54.67
